Workbook
Name Complexity: #REF!
Name DocumentTypes: [1]Lookups!$A$24:$A$28
Name Open: #REF!
Name Requirementstatus: #REF!
Name Status: #REF!
Name YesNo: [2]Lookups!$A$1:$A$2

Sheet Table of Contents
A1: TABLE OF CONTENTS
A2: Client: | B2: SECURA Insurance Companies
A3: Phase: | B3: Product Simplification
A4: # | B4: TAB NAME | C4: DESCRIPTION
A5: 2 | B5: Version History | C5: Anytime you make a change or update to the document
A6: 3 | B6: Definitions | C6: These should remain unchanged, use this as a reference/glossary to understand terms
A7: 4 | B7: Product Contacts | C7: Who are the client Product SME's that helped define the Product Strategy
A8: 5 | B8: Product Inventory | C8: A single source view of ALL Products/Processes during the Product Strategy & Rationalization phases
A9: 6 | B9: Product Component Model | C9: The focal point of this document, where you document the Product Architecture. This is the foundation that comes out of your Product Definition & Development phase
A10: 7 | B10: PCM Dropdowns | C10: This should stay unchanged, and should remain as a hidden tab
A13: TABS LEGEND | D13: MAIN COLUMNS LEGEND | G13: Start here
B14: Administrative | E14: Product Hierarchy
B15: Supplemental/Supporting | E15: Product Details
B16: Primary/Main Focal Point | E16: Product Applicability
B17: Hidden/Unchanged

Sheet Version History
A1: VERSION HISTORY
A2: Client: | B2: ='Table of Contents'!B2 -> SECURA Insurance Companies
A3: Phase: | B3: ='Table of Contents'!B3 -> Product Simplification
A4: DATE | B4: VERSION | C4: SUMMARY OF UPDATE | D4: NAME
A5: 44854 | B5: 1 | C5: Created this example for you | D5: Tulio

Sheet Definitions
A1: DEFINITIONS - PRODUCT COMPONENT MODEL
A2: Client: | B2: ='Table of Contents'!B2 -> SECURA Insurance Companies
A3: Phase: | B3: ='Table of Contents'!B3 -> Product Simplification
A4: COLUMN NAME | B4: DEFINITION | C4: EXAMPLE
A5: Product | B5: A Product is a Line of Business or multiple Lines of Business presented for sale and distribution in the market by an insurer
A6: LOB | B6: A Line of Business (LOB) is a specific Product, which contains a group of related Coverages
A7: Coverage | B7: Coverage is the scope of protection against a specific loss or liability within a Line of Business
A8: Sub-Coverage | B8: Sub-Coverage is the scope of proection against a specific loss or liability, and has a parent-child relationship with a Coverage. Often times offered as supplementary or optional for additional premium
A9: Claims Basis | B9: Occurrence: An occurrence policy protects a business from any covered incident that happens during the policy period—regardless of when a claim is reported. Claims-made: A claims-made policy provides coverage for claims that occur—and are reported—within the specific time period set forth by the policy. | C9: Occurrence: Bob the business owner purchased an occurrence policy in 2015 but switched to a new form of coverage in 2020. Bob got sued in 2022 for an incident that occurred in 2017. In this instance, Bob is still covered by his original occurrence policy, because it was active at the time of the incident. Claims-made: Bob the businessman purchased a claims-made policy in 2015 and continued coverage through 2017, then cancels. He does not purchase any extension (tail coverage) on the policy’s original limits. In 2018, Bob is sued for an incident that occurred in 2016. Since the claims-made policy is no longer in effect and he did not purchase tail coverage, Bob is the liable party—meaning he is obligated to pay for damages, as his former insurance carrier does not cover it.
A10: Coverage Requirement | B10: Determines whether the Coverage is Mandatory or Optional Mandatory: Mandatory insurance is any type of insurance that an individual or business is legally required to buy. Optional: Any type of insurance that is not required, and may be added for additional premium. | C10: Mandatory: Insurance is mandatory for individuals and businesses that want to engage in certain financially risky activities, such as operating an automobile, owning a home or operating a business with employees. Optional: Any type of insurance that is not required, and may be added for additional premium.
A11: Coverage Scope | B11: First Party: First-party insurance is obtained for the policyholder (otherwise known as the named insured) to cover losses or damages to the policyholder’s property or themselves. Third Party: Third-party insurance is purchased to protect the insured against liability for losses or damages that the insured causes to another individual or to their property. | C11: First Party: Common types of first-party insurance claims -- Health Insurance, Medical payments under an Auto or Homeowner policy, PIP under Auto, Underinsured or Uninsured motorist. Third Party: Common types of third-party insurance claims -- CGL coverage, Liability under Auto, Commercial Auto, Umbrella policies, Professional Liability, Product Liability, Animal Liability insurance.
A12: Coverage Effect | B12: What effect does this coverage have? (Rebecca/Robert could you please help us define these?) Grants Coverage Restricts Broadens Amends Administrative
A13: Premium Generating? | B13: Whether there is any impact to Premium (i.e. Additional premium, etc…) Yes: Yes this impacts/generates Premium No: This does not impact/generate any Premium
A14: Rating Bureau? | B14: Determines whether this carrier participates in any organization that standardizes insurance underwriting. | C14: Examples include: ISO, ACORD, AAIS, NCCI. Any organization that provides standardized Forms, Insurance Raters, and aids with filings and regulations.
A15: Proprietary | B15: Determines if they handle all of their underwriting in-house. | C15: In this case: The carrier has their own Raters, Forms, carries out their own filings, and has a dedicated team that deals with regulators.
A16: No. of Forms | B16: Total count of all coverage forms per Product Hierarchy
A17: State Applicability | B17: The State(s) to which the Product applies
A18: W.R.A.P | B18: SECURA's proprietary endorsement, which adds coverages/limits/etc... With Reliable Added Protection
A20: Insurance Guiding Principles | B20: If there is no Limit, Premium, Deductible, then not included in this document (i.e. Exclusions)

Sheet Product Contacts
A1: PRODUCT CONTACTS
A2: Client: | B2: ='Table of Contents'!B2 -> SECURA Insurance Companies
A3: Phase: | B3: ='Table of Contents'!B3 -> Product Simplification
A4: PRODUCT | B4: PRODUCT OWNER | C4: EMAIL ADDRESS | D4: PHONE NUMBER | E4: DATE OF FIRST MEET
A5: Commercial Property | B5: Jeri Eveland | C5: Jeri_Eveland@SECURA.net | D5: (123)456-7890

Sheet Product Inventory
A1: PRODUCT INVENTORY
B2: Client: | C2: ='Table of Contents'!B2 -> SECURA Insurance Companies
B3: Phase: | C3: ='Table of Contents'!B3 -> Product Simplification
B4: OWNERSHIP | D4: POLICY | H4: PRICING/ACTUARIAL | L4: UNDERWRITING | P4: DOCUMENTS | T4: CLAIMS | X4: BILLING
F5: CURRENT | G5: TARGET | H5: CURRENT | I5: TARGET | J5: CURRENT | K5: TARGET | L5: CURRENT | M5: TARGET | N5: CURRENT | O5: TARGET | P5: CURRENT | Q5: TARGET | R5: CURRENT | S5: TARGET | V5: CURRENT | W5: TARGET | X5: CURRENT | Y5: TARGET
A6: # | B6: PRODUCT OWNER | C6: PRODUCT | D6: POLICY PREMIUM | E6: POLICY COUNT (Approximate) | F6: POLICY PROCESSING SYSTEM | H6: NUMBER OF RATING ALGORITHMS - STEPS | J6: NUMBER OF COVERAGES | L6: NUMBER OF WRITING COMPANIES | N6: NUMBER OF UNDERWRITING RULES | P6: NUMBER OF FORMS | R6: DOCUMENT STORAGE SYSTEM | T6: CLAIMS COUNTS (2021 Annual) | U6: CLAIMS COUNTS (Open as of June 2022) | V6: CLAIMS SYSTEM SUPPORTED | X6: BILLING SYSTEM SUPPORTED
A7: 1 | C7: Commercial Property Product | D7: 500K | E7: 0 | F7: PowerWriter
A8: 2
A9: 3
A10: 4 | C10: Product #2 | D10: 2M
A11: 5
A12: 6
A13: 7
A14: 8
A15: 9
A16: 10
A17: 11
A18: 12
A19: 13
A20: 14 | C20: Product #3
A21: 15
A22: 16
A23: 17 | C23: Product #4
A24: 18
A25: 19
A26: 20 | C26: Product #5
A27: 21
A28: 22
A29: 23 | C29: Product #6
A30: 24
A31: 25

Sheet Product Component Model
A2: Client Name:
A3: Phase:
B4: PRODUCT HEIRARCHY | F4: COVERAGE DETAILS | Q4: STATE APPLICABILITY
A5: ID | B5: PRODUCT | C5: LOB | D5: COVERAGE | E5: SUB COVERAGE | F5: COVERAGE FORM(S) | G5: FORM NUMBER | H5: EDITION DATE | I5: CLAIMS BASIS | J5: COVERAGE REQUIREMENT | K5: COVERAGE SCOPE | L5: COVERAGE EFFECT | M5: PREMIUM GENERATING? | N5: RATING BUREAU | O5: PROPRIETARY? | P5: CLAIMS EXPENSE W/I LIMIT? | Q5: ALL 14 | R5: AZ | S5: CO | T5: IL | U5: IN | V5: IA | W5: KS | X5: KY | Y5: MI | Z5: MN | AA5: MO | AB5: ND | AC5: PA | AD5: UT | AE5: WI | AF5: QUESTIONS / COMMENTS
A6: PRCOV001.0 | B6: Monoline Building and Personal Property | C6: Commercial Property | D6: Building | F6: Building and Personal Property | G6: CP 00 10 | H6: 06/07
A7: PR.COV001.0 | B7: Monoline Building and Personal Property | C7: Commercial Property | D7: Building | F7: Building and Personal Property | G7: CP 00 10 | H7: 06/07
A8: PR.COV001.0 | B8: Monoline Building and Personal Property | C8: Commercial Property | D8: Building | F8: Building and Personal Property | G8: CP 00 10 | H8: 06/07 | I8: Occurrence | J8: Mandatory | K8: First Party | L8: Grants Coverage | M8: Yes | N8: ISO | O8: No
A9: PR.COV001.1 | B9: Monoline Building and Personal Property | C9: Commercial Property | D9: Building | E9: Preservation Of Property | F9: Building and Personal Property | G9: CP 00 10 | H9: 06/07 | I9: Occurrence | J9: Optional | K9: First Party | L9: Broadens | N9: ISO | O9: No
A10: PR.COV001.2 | B10: Monoline Building and Personal Property | C10: Commercial Property | D10: Building | E10: Outdoor Signs | F10: Building and Personal Property | G10: CP 00 10 | H10: 06/07 | I10: Occurrence | J10: Optional | K10: First Party | L10: Broadens | N10: ISO | O10: No | AF10: Additional Coverage Forms: Outdoor Signs Endorsement, Universal Wrap, Human Services Wrap
A11: PR.COV001.3 | B11: Monoline Building and Personal Property | C11: Commercial Property | D11: Building | E11: Newly Acquired Or Constructed Property | F11: Building and Personal Property | G11: CP 00 10 | H11: 06/07 | I11: Occurrence | J11: Optional | K11: First Party | L11: Broadens | N11: ISO | O11: No | AF11: Additional Coverage Forms: Universal Wrap Elite Universal Wrap
A12: PR.COV001.4 | B12: Monoline Building and Personal Property | C12: Commercial Property | D12: Building | E12: Increased Cost Of Construction | F12: Building and Personal Property | G12: CP 00 10 | H12: 06/07 | I12: Occurrence | J12: Optional | K12: First Party | L12: Broadens | N12: ISO | O12: No | AF12: Additional Coverage Forms: Ordinance or Law Coverage Endorsement, Universal WRAP, Human Services WRAP, Golf Course Wrap
A13: PR.COV001.5 | B13: Monoline Building and Personal Property | C13: Commercial Property | D13: Building | E13: Debris Removal | F13: Building and Personal Property | G13: CP 00 10 | H13: 06/07 | I13: Occurrence | J13: Optional | K13: First Party | L13: Broadens | N13: ISO | O13: No
A14: PR.COV001.6 | B14: Monoline Building and Personal Property | C14: Commercial Property | D14: Building | E14: Fire Department Service Charge | F14: Building and Personal Property | G14: CP 00 10 | H14: 06/07 | I14: Occurrence | J14: Optional | K14: First Party | L14: Broadens | N14: ISO | O14: No
A15: PR.COV001.7 | B15: Monoline Building and Personal Property | C15: Commercial Property | D15: Building | E15: Volcanic Eruption | F15: Earthquake and Volcanic Eruption Endorsement | G15: CP 10 40 | H15: 08/99 | I15: Occurrence | J15: Optional | K15: First Party | L15: Grants Coverage | M15: Yes | N15: ISO | O15: No
A16: PR.COV001.8 | B16: Monoline Building and Personal Property | C16: Commercial Property | D16: Building | E16: Sprinkler Leakage | F16: Earthquake and Volcanic Eruption Endorsement | G16: CP 10 40 | H16: 02/19 | I16: Occurrence | J16: Optional | K16: First Party | L16: Grants Coverage | M16: Yes | N16: ISO | O16: No | AF16: Additional Coverage Forms: Human Services WRAP
A17: PR.COV001.9 | B17: Monoline Building and Personal Property | C17: Commercial Property | D17: Building | E17: Utility Services | F17: Utility Services - Direct Damage Endorsement | G17: CP 04 17 | H17: 10/12 | I17: Occurrence | J17: Optional | K17: First Party | L17: Grants Coverage | M17: Yes | N17: ISO | O17: No | AF17: Additional Coverage Forms: Human Services WRAP
A18: PR.COV001.10 | B18: Monoline Building and Personal Property | C18: Commercial Property | D18: Building | E18: Flood | F18: Flood Coverage Endorsement | G18: CP 10 65 | H18: 10/12 | I18: Occurrence | J18: Optional | K18: First Party | L18: Grants Coverage | N18: ISO | O18: No
A19: PR.COV001.11 | B19: Monoline Building and Personal Property | C19: Commercial Property | D19: Building | E19: Outdoor Trees, Shrubs & Plants | F19: Outdoor Trees, Shrubs & Plants Endorsement | G19: CP 14 30 | H19: 10/12 | I19: Occurrence | J19: Optional | K19: First Party | L19: Grants Coverage | M19: Yes | N19: ISO | O19: No | AF19: Additional Coverage Forms: Universal Wrap Coverage Form, Elite Wrap Coverage Form, Human Services Wrap, Inn Wrap, Golf Course Wrap
A20: PR.COV001.12 | B20: Monoline Building and Personal Property | C20: Commercial Property | D20: Building | E20: Fences And Antennas | F20: Outdoor Trees, Shrubs & Plants Endorsement | G20: CPT 90 99 | H20: 01/13 | I20: Occurrence | J20: Optional | K20: First Party | L20: Grants Coverage | M20: Yes | N20: ISO | O20: Yes | AF20: Additional Coverage Forms: Universal Wrap Coverage Form Elite Wrap Coverage Form Human Services Wrap Fences and Antennas
A21: PR.COV001.13 | B21: Monoline Building and Personal Property | C21: Commercial Property | D21: Building | E21: Green Upgrades | F21: Increased Cost of Loss and Related Expenses for Green Upgrades Endorsement | G21: CP 04 02 | H21: 10/12 | I21: Occurrence | J21: Optional | K21: First Party | L21: Grants Coverage | M21: Yes | N21: ISO | O21: No
A22: PR.COV001.14 | B22: Monoline Building and Personal Property | C22: Commercial Property | D22: Building | E22: Related Expenses | F22: Increased Cost of Loss and Related Expenses for Green Upgrades Endorsement | G22: CP 04 02 | H22: 10/12 | I22: Occurrence | J22: Optional | K22: First Party | L22: Grants Coverage | M22: Yes | N22: ISO | O22: No
A23: PR.COV001.15 | B23: Monoline Building and Personal Property | C23: Commercial Property | D23: Building | E23: Property Damage - Water Back-Up And Sump Overflow (Not Flood-Related) | F23: Water Back-up And Sump Overflow (Not Flood-Related) Endorsement | G23: CPE 06 96 | H23: 01/13 | I23: Occurrence | J23: Optional | K23: First Party | L23: Broadens | M23: Yes | N23: N/A
A24: PR.COV001.16 | B24: Monoline Building and Personal Property | C24: Commercial Property | D24: Building | E24: Public Safety Service Charges | F24: Universal Wrap | G24: CPT 90 99 | H24: 01/13 | I24: Occurrence | J24: Optional | K24: First Party | L24: Amends | N24: N/A | O24: Yes | AF24: This coverage replaces Fire Department Service Charge with ALL Public Service Charges. Additional Coverage Forms: Elite Universal WRAP, Human Services Wrap
A25: PR.COV001.17 | B25: Monoline Building and Personal Property | C25: Commercial Property | D25: Building | E25: Lock Replacement Due To Theft Of Keys Or Transmitters | F25: Universal Wrap | G25: CPT 90 99 | H25: 01/13 | I25: Occurrence | J25: Optional | K25: First Party | L25: Amends | N25: N/A | O25: Yes | AF25: Additional Coverage Forms: Elite Universal Wrap Coverage Form Human Services Wrap
A26: PR.COV001.18 | B26: Monoline Building and Personal Property | C26: Commercial Property | D26: Building | E26: Tenant Glass Breakage | F26: Universal Wrap | G26: CPT 90 99 | H26: 01/13 | I26: Occurrence | J26: Optional | K26: First Party | L26: Grants Coverage | M26: Yes | N26: N/A | O26: Yes | AF26: Additional Coverage Forms: Elite Wrap Coverage Form
A27: PR.COV001.19 | B27: Monoline Building and Personal Property | C27: Commercial Property | D27: Building | E27: Unscheduled Structures (Garages, Storage Buildings And Other Structures) | F27: Universal Wrap | G27: CPT 90 99 | H27: 01/13 | I27: Occurrence | J27: Optional | K27: First Party | L27: Grants Coverage | M27: Yes | N27: N/A | O27: Yes | AF27: Additional Coverage Forms: Elite Wrap Coverage Form
A28: PR.COV001.20 | B28: Monoline Building and Personal Property | C28: Commercial Property | D28: Building | E28: Tenant Building | F28: Universal Wrap | G28: CPT 90 99 | H28: 01/13 | I28: Occurrence | J28: Optional | K28: First Party | L28: Grants Coverage | N28: N/A | O28: Yes
A29: PR.COV001.21 | B29: Monoline Building and Personal Property | C29: Commercial Property | D29: Building | E29: Contract Penalty Costs | F29: Elite Universal Wrap | G29: CPT 79 99 | H29: 01/13 | I29: Occurrence | J29: Optional | K29: First Party | L29: Grants Coverage | N29: N/A | O29: Yes
A30: PR.COV001.22 | B30: Monoline Building and Personal Property | C30: Commercial Property | D30: Building | E30: Realty Tax-Increased Assessment | F30: Elite Universal Wrap | G30: CPT 79 99 | H30: 01/13 | I30: Occurrence | J30: Optional | K30: First Party | L30: Grants Coverage | N30: N/A | O30: Yes
A31: PR.COV001.23 | B31: Monoline Building and Personal Property | C31: Commercial Property | D31: Building | E31: Security After Loss | F31: Elite Universal Wrap | G31: CPT 79 99 | H31: 01/13 | I31: Occurrence | J31: Optional | K31: First Party | L31: Grants Coverage | N31: N/A | O31: Yes
A32: PR.COV001.24 | B32: Monoline Building and Personal Property | C32: Commercial Property | D32: Building | E32: Vacancy Permit | F32: Vacancy Permit | G32: CP 04 50 | H32: 07/88 | I32: Occurrence | J32: Optional | K32: First Party
A33: PR.COV001.25 | B33: Monoline Building and Personal Property | C33: Commercial Property | D33: Building | E33: Claim Data Or Inventory Expense | F33: Human Services Wrap | G33: CPT 35 00 | H33: 11/20 | I33: Occurrence | J33: Optional | K33: First Party | L33: Grants Coverage | N33: N/A | O33: Yes | AF33: Additional Coverage Forms: Golf Course Wrap
A34: PR.COV001.26 | B34: Monoline Building and Personal Property | C34: Commercial Property | D34: Building | E34: Swimming Pools And Inground Sprinkler Systems | F34: Golf Course Property Wrap | G34: CPT 48 00 | H34: 04/21
A35: PR.COV001.27 | B35: Monoline Building and Personal Property | C35: Commercial Property | D35: Building | E35: Theft Of Telephone Or Dataline Services | F35: Golf Course Property Wrap | G35: CPT 48 00 | H35: 04/21 | I35: Occurrence | J35: Optional | K35: First Party | L35: Grants Coverage | M35: Yes | N35: N/A | O35: Yes
A36: PR.COV002.0 | B36: Monoline Building and Personal Property | C36: Commercial Property | D36: Ordinance or Law | E36: Ordinance Or Law | F36: Ordinance or Law Coverage Endorsement | G36: CP 04 05 | H36: 04/02 | I36: Occurrence | J36: Optional | K36: First Party | L36: Grants Coverage | M36: Yes | N36: N/A | O36: Yes | AF36: Move down
A37: PR.COV002.1 | B37: Monoline Building and Personal Property | C37: Commercial Property | D37: Ordinance or Law | E37: Coverage For Loss To The Undamaged Portion Of The Building | F37: Ordinance or Law Coverage Endorsement | G37: CP 04 05 | H37: 09/17 | I37: Occurrence | J37: Optional | K37: First Party | L37: Grants Coverage | M37: Yes | N37: ISO | O37: No | AF37: Additional Coverage Forms: Functional Building Valuation Endorsement, Universal Wrap, Elite Wrap
A38: PR.COV002.2 | B38: Monoline Building and Personal Property | C38: Commercial Property | D38: Ordinance or Law | E38: Demolition Cost | F38: Ordinance or Law Coverage Endorsement | G38: CP 04 05 | H38: 09/17 | I38: Occurrence | J38: Optional | K38: First Party | L38: Grants Coverage | M38: Yes | N38: ISO | O38: No | AF38: Additional Coverage Forms: Universal WRAP, Elite Universal WRAP, Human Services WRAP, Golf Course Wrap
A39: PR.COV002.3 | B39: Monoline Building and Personal Property | C39: Commercial Property | D39: Ordinance or Law | E39: Increased Cost Of Construction | F39: Ordinance or Law Coverage Endorsement | G39: CP 04 05 | H39: 09/17 | I39: Occurrence | J39: Optional | K39: First Party | L39: Grants Coverage | M39: Yes | N39: ISO | O39: No | AF39: Additional Coverage Forms: Universal WRAP, Elite Universal WRAP, Human Services WRAP, Golf Course Wrap
A40: PR.COV003.0 | B40: Monoline Building and Personal Property | C40: Commercial Property | D40: Business Personal Property | F40: Building and Personal Property | G40: CP 00 10 | H40: 06/07 | I40: Occurrence | J40: Mandatory | K40: First Party | L40: Grants Coverage | M40: Yes | N40: ISO | O40: No
A41: PR.COV003.1 | B41: Monoline Building and Personal Property | C41: Commercial Property | D41: Business Personal Property | E41: Preservation Of Property | F41: Building and Personal Property | G41: CP 00 10 | H41: 06/07 | I41: Occurrence | J41: Optional | K41: First Party | L41: Broadens | N41: ISO | O41: No
...

Sheet Property Forms Usage
A1: Form Type | B1: Form Number | C1: Form Name | D1: Category | E1: Proprietary or ISO | F1: Count of Forms | H1: PCM? | I1: Owner | J1: Comments | K1: Complete? | L1: Prop Or ISO | M1: PCM?
A3: PR | B3: CP 0090 0788 | C3: COMMERCIAL PROPERTY CONDITIONS | D3: POLICY CONDITIONS | E3: ISO | F3: 30914 | H3: N/A | I3: Tulio | L3: ISO | M3: N/A
A4: PR | B4: CP 0140 0706 | C4: EXCLUSION OF LOSS DUE TO VIRUS OR BACTERIA | D4: EXCLUSION | E4: ISO | F4: 30914 | H4: N/A | I4: Sal | L4: Proprietary | M4: ?
A5: PR | B5: CP 1032 0808 | C5: WATER EXCLUSION ENDORSEMENT | D5: EXCLUSION | E5: ISO | F5: 30913 | H5: N/A | I5: Sal | M5: X
A6: PR | B6: CP 1030 0607 | C6: CAUSES OF LOSS – SPECIAL FORM | D6: EXCLUSION | E6: ISO | F6: 30882 | H6: N/A
A7: PR | B7: CP 0010 0607 | C7: BUILDING & PERSONAL PROPERTY COVERAGE | D7: BASE COVERAGE FORM | E7: ISO | F7: 30859 | H7: X | I7: Tulio
A8: PR | B8: CPE 0100 2105 | C8: COMPUTER AMENDATORY | D8: ENDORSEMENT | E8: Proprietary | F8: 30847 | H8: X | I8: Sal
A9: PR | B9: CPE 1075 2105 | C9: EXCLUSION – CYBER INCIDENTS PROPERTY | D9: EXCLUSION | E9: Proprietary | F9: 30847 | H9: ? | I9: Sal | J9: **I believe this grants back: Spoiler Coverage (Power Outage) & Computer Fraud
A10: PR | B10: CPT 9000 1301 | C10: UNIVERSAL WRAP SCHEDULE | D10: POLICY CONDITIONS | E10: Proprietary | F10: 27599 | H10: N/A | I10: Sal | J10: **Just lists out limits that are being amended
A11: PR | B11: CPT 9099 1301 | C11: UNIVERSAL WRAP COVERAGE FORM | D11: WRAP | E11: Proprietary | F11: 27599 | H11: X | I11: Sal
A12: PR | B12: HSB 5000 1301 | C12: EQUIPMENT BREAKDOWN WRAP CAUSES OF LOSS - BREAKDOWN | D12: OTHER COVERAGE FORM | E12: Proprietary | F12: 27423 | H12: X | I12: Sal
A13: PR | B13: CP 1504 0607 | C13: DISCRETIONARY PAYROLL EXPENSE | D13: POLICY CONDITIONS | E13: ISO | F13: 23128 | H13: X | I13: Sal | J13: **Schedules type of employees/max # of days
A14: PR | B14: CP 0030 0607 | C14: BUSINESS INCOME AND EXTRA EXPENSE COVERAGE | D14: BASE COVERAGE FORM | E14: ISO | F14: 23112 | H14: X | I14: Rohit
A15: PR | B15: CPE 0696 1301 | C15: Water Back-up And Sump Overflow (Not Flood-Related) | D15: OTHER COVERAGE FORM | E15: Proprietary | F15: 20241 | H15: X | I15: Sal
A16: PR | B16: CPE 1555 1301 | C16: BUSINESS INCOME – ACTUAL LOSS SUSTAINED | D16: POLICY CONDITIONS | E16: Proprietary | F16: 18447 | H16: N/A | I16: Sal | J16: This form doesn't add coverage, it modifies the terms of coverage under Business Income (SS)
A17: PR | B17: CP 1556 0607 | C17: BUSINESS INCOME CHANGES – BEGINNING OF THE PERIOD OF RESTORATION | D17: ENDORSEMENT | E17: ISO | F17: 14730 | H17: N/A | I17: Sal
A18: PR | B18: CPT 5500 1301 | C18: CONTRACTOR AND SERVICES WRAP | D18: WRAP | E18: Proprietary | F18: 9311 | H18: X | I18: Sal
A19: PR | B19: CP 0113 1002 | C19: WISCONSIN CHANGES | D19: ENDORSEMENT | E19: ISO | F19: 8452 | H19: N/A | I19: Rohit
A20: PR | B20: CP 1550 1185 | C20: RADIO OR TELEVISION ANTENNAS – BUSINESS INCOME OR EXTRA EXPENSE | D20: ENDORSEMENT | E20: ISO | F20: 7819 | H20: N/A | I20: Rohit
A21: PR | B21: CP 1218 0607 | C21: LOSS PAYABLE PROVISIONS | D21: POLICY CONDITIONS | E21: ISO | F21: 6466 | H21: N/A | I21: Rohit
A22: PR | B22: CP 0108 0520 | C22: MINNESOTA CHANGES | D22: POLICY CONDITIONS | E22: ISO | F22: 4657 | H22: ? | J22: Can't find this form (SS)
A23: PR | B23: CP 0150 1000 | C23: MINNESOTA CHANGES – REPLACEMENT COST PERSONAL PROPERTY | D23: POLICY CONDITIONS | E23: ISO | F23: 4116 | H23: N/A | J23: Updates existing coverage
A24: PR | B24: CP 0149 0607 | C24: ILLINOIS CHANGES – ARTIFICIALLY GENERATED ELECTRICAL CURRENT EXCLUSION | D24: EXCLUSION | E24: ISO | F24: 2565 | H24: N/A
A25: PR | B25: CP 0157 0918 | C25: MINNESOTA CHANGES - COINSURANCE | D25: POLICY CONDITIONS | E25: ISO | F25: 2386 | H25: N/A
A26: PR | B26: CP 0128 0700 | C26: MISSOURI – CALCULATION OF ADDITIONAL PREMIUM | D26: ENDORSEMENT | E26: ISO | F26: 2331 | H26: N/A | I26: Tulio
A27: PR | B27: CP 1270 0996 | C27: JOINT OR DISPUTED LOSS AGREEMENT | D27: POLICY CONDITIONS | E27: ISO | F27: 2327 | H27: N/A | I27: Sal | J27: * Requires a CP + Builders' Risk policy by different insurers - describes terms of how a loss to covered property will be payed
A28: PR | B28: CPE 1036 1305 | C28: LIMITATIONS ON COVERAGE FOR ROOF SURFACING | D28: POLICY CONDITIONS | E28: Proprietary | F28: 2278 | H28: N/A | I28: Sal | J28: **This restricts coverage caused by wind/hail to the roof of the building
A29: PR | B29: CP 0166 0900 | C29: KENTUCKY CHANGES | D29: ENDORSEMENT | E29: ISO | F29: 2253 | H29: N/A | I29: Tulio
A30: PR | B30: CP 1040 0899 | C30: EARTHQUAKE AND VOLCANIC ERUPTION ENDORSEMENT | D30: ENDORSEMENT | E30: ISO | F30: 2248 | H30: X | I30: Tulio
A31: PR | B31: CP 0132 0120 | C31: ARIZONA CHANGES | D31: ENDORSEMENT | E31: ISO | F31: 2223 | H31: N/A | I31: Tulio
A32: PR | B32: CP 0146 0894 | C32: ARIZONA CHANGES | D32: ENDORSEMENT | E32: ISO | F32: 2195 | H32: ? | I32: Tulio | J32: This removes Fire Dept. Service Charge… from ALL Property Coverages
A33: PR | B33: CPE 0200 1301 | C33: GREENHOUSE VALUATION AMENDMENT | D33: POLICY CONDITIONS | E33: Proprietary | F33: 2193 | H33: N/A | I33: Sal | J33: **This restricts certain coverage and terms applicable to Greenhouses only (ex: ACV doesn't apply, Coinsurance applies, terms to be covered are added - 'temp must be > 40 degrees)
A34: PR | B34: CPT 7999 1301 | C34: ELITE UNIVERSAL WRAP COVERAGE FORM | D34: WRAP | E34: Proprietary | F34: 1962 | H34: X | I34: Sal
A35: PR | B35: CP 0120 0421 | C35: MICHIGAN CHANGES | D35: ENDORSEMENT | E35: ISO | F35: 1910 | H35: N/A | I35: Tulio
A36: PR | B36: CPT 7900 1301 | C36: MICHIGAN CHANGES | D36: ENDORSEMENT | E36: Proprietary | F36: 1830 | H36: N/A | I36: Tulio | J36: This is just a schedule for the Michigan Wrapper
A37: PR | B37: CPE 2411 1106 | C37: MISSOURI CHANGES – LOSS NOTICE REQUIREMENTS | D37: OTHER (Notices, Dec, etc.) | E37: Proprietary | F37: 1823 | H37: N/A
A38: PR | B38: CP 1221 0208 | C38: LOSS PAYABLE PROVISIONS - MINNESOTA | D38: POLICY CONDITIONS | E38: ISO | F38: 1451 | H38: N/A
A39: PR | B39: CP 0114 1115 | C39: NORTH DAKOTA CHANGES | D39: ENDORSEMENT | E39: ISO | F39: 1400 | H39: N/A | I39: Tulio | J39: Valued Policies 2. might be good to double check with Rebecca
A40: PR | B40: CPT 4500 1301 | C40: RESTAURANT WRAP | D40: WRAP | E40: Proprietary | F40: 1291 | H40: X | I40: Sal
A41: PR | B41: CP 0152 0796 | C41: INDIANA CHANGES – RIGHTS OF RECOVERY | D41: ENDORSEMENT | E41: ISO | F41: 1200 | H41: N/A | I41: Tulio
...

Sheet Coverage Summary
D1: Required | E1: Universal Wraps Include All Base Coverages | G1: Trade-Specific WRAPs Include Coverages From BPP & Universal/Elite
A2: ID | B2: Coverage | C2: Sub-Coverage | D2: Monoline Building and Personal Property | E2: Universal Coverages | F2: Elite Universal Coverages | G2: Inn Product Coverages | H2: Golf Course Coverages | I2: Human Services Coverages | J2: Restaurant Coverages | K2: Contractor and Services Coverages | L2: Green Industry Contractor Coverages | M2: Equipment Breakdown Coverages | N2: Tank Leakage Coverages | O2: Manufacturer Coverages
B3: Building | D3: X | E3: X | F3: X | G3: X | H3: X | I3: X | J3: X | K3: X | L3: X | M3: X | N3: X | O3: X
B4: Building | C4: Preservation of Property | D4: X | E4: X | F4: X | G4: X | H4: X | I4: X | J4: X | K4: X | L4: X | M4: X | N4: X | O4: X
B5: Building | C5: Outdoor Signs | D5: X | E5: X | F5: X | G5: X | H5: X | I5: X | J5: X | K5: X | L5: X | M5: X | N5: X | O5: X
B6: Building | C6: Newly Acquired or Constructed Property | D6: X | E6: X | F6: X | G6: X | H6: X | I6: X | J6: X | K6: X | L6: X | M6: X | N6: X | O6: X
B7: Building | C7: Increased Cost of Construction | D7: X | E7: X | F7: X | G7: X | H7: X | I7: X | J7: X | K7: X | L7: X | M7: X | N7: X | O7: X
B8: Building | C8: Debris Removal | D8: X | E8: X | F8: X | G8: X | H8: X | I8: X | J8: X | K8: X | L8: X | M8: X | N8: X | O8: X
B9: Building | C9: Fire Department Service Charge | D9: X | E9: X | F9: X | G9: X | H9: X | I9: X | J9: X | K9: X | L9: X | M9: X | N9: X | O9: X
B10: Building | C10: Public Safety Service Charges | E10: X | F10: X | G10: X | H10: X | I10: X | J10: X | K10: X | L10: X | M10: X | N10: X | O10: X
B11: Building | C11: Lock Replacement Due to Theft of Keys or Transmitters | E11: X | F11: X | G11: X | H11: X | I11: X | J11: X | K11: X | L11: X | M11: X | N11: X | O11: X
B12: Building | C12: Tenant Glass Breakage | E12: X | F12: X | G12: X | H12: X | I12: X | J12: X | K12: X | L12: X | M12: X | N12: X | O12: X
B13: Building | C13: Unscheduled Structures (Garages, Storage Buildings and Other Structures) | E13: X | F13: X | G13: X | H13: X | I13: X | J13: X | K13: X | L13: X | M13: X | N13: X | O13: X
B14: Building | C14: Tenant Building | E14: X | F14: X | G14: X | H14: X | I14: X | J14: X | K14: X | L14: X | M14: X | N14: X | O14: X
B15: Building | C15: Contract Penalty Costs | F15: X
B16: Building | C16: Realty Tax-Increased Assessment | F16: X
B17: Building | C17: Security After Loss | F17: X
B18: Building | C18: Claim Data or Inventory Expense | H18: X | I18: X
B19: Building | C19: Swimming Pools And Inground Sprinkler Systems | H19: X
B20: Business Personal Property | D20: X | E20: X | F20: X | G20: X | H20: X | I20: X | J20: X | K20: X | L20: X | M20: X | N20: X | O20: X
B21: Business Personal Property | C21: Preservation of Property | D21: X | E21: X | F21: X | G21: X | H21: X | I21: X | J21: X | K21: X | L21: X | M21: X | N21: X | O21: X
B22: Business Personal Property | C22: Outdoor Signs | D22: X | E22: X | F22: X | G22: X | H22: X | I22: X | J22: X | K22: X | L22: X | M22: X | N22: X | O22: X
B23: Business Personal Property | C23: Newly Acquired or Constructed Property | D23: X | E23: X | F23: X | G23: X | H23: X | I23: X | J23: X | K23: X | L23: X | M23: X | N23: X | O23: X
B24: Business Personal Property | C24: Electronic data | D24: X | E24: X | F24: X | G24: X | H24: X | I24: X | J24: X | K24: X | L24: X | M24: X | N24: X | O24: X
B25: Business Personal Property | C25: Personal Effects and Property of Others | D25: X | E25: X | F25: X | G25: X | H25: X | I25: X | J25: X | K25: X | L25: X | M25: X | N25: X | O25: X
B26: Business Personal Property | C26: Valuable Papers & Records (other than Electronic Data) | D26: X | E26: X | F26: X | G26: X | H26: X | I26: X | J26: X | K26: X | L26: X | M26: X | N26: X | O26: X
B27: Business Personal Property | C27: Property Off-Premises | D27: X | E27: X | F27: X | G27: X | H27: X | I27: X | J27: X | K27: X | L27: X | M27: X | N27: X | O27: X
B28: Business Personal Property | C28: Non-owned detached trailers | D28: X | E28: X | F28: X | G28: X | H28: X | I28: X | J28: X | K28: X | L28: X | M28: X | N28: X | O28: X
B29: Business Personal Property | C29: Debris Removal | D29: X | E29: X | F29: X | G29: X | H29: X | I29: X | J29: X | K29: X | L29: X | M29: X | N29: X | O29: X
B30: Business Personal Property | C30: Fire Department Service Charge | D30: X | E30: X | F30: X | G30: X | H30: X | I30: X | J30: X | K30: X | L30: X | M30: X | N30: X | O30: X
B31: Business Personal Property | C31: Public Safety Service Charges | E31: X | F31: X | G31: X | H31: X | I31: X | J31: X | K31: X | L31: X | M31: X | N31: X | O31: X
B32: Business Personal Property | C32: Fine Arts at Described Premises | E32: X | F32: X | G32: X | H32: X | I32: X | J32: X | K32: X | L32: X | M32: X | N32: X | O32: X
B33: Business Personal Property | C33: Fire Extinguisher Recharge | E33: X | F33: X | G33: X | H33: X | I33: X | J33: X | K33: X | L33: X | M33: X | N33: X | O33: X
B34: Business Personal Property | C34: Accounts Receivable (Other Than Electronic Data) | E34: X | F34: X | G34: X | H34: X | I34: X | J34: X | K34: X | L34: X | M34: X | N34: X | O34: X
B35: Business Personal Property | C35: Landlord Furnishings | E35: X | F35: X | G35: X | H35: X | I35: X | J35: X | K35: X | L35: X | M35: X | N35: X | O35: X
B36: Business Personal Property | C36: Theft of Building Materials | E36: X | F36: X | G36: X | H36: X | I36: X | J36: X | K36: X | L36: X | M36: X | N36: X | O36: X
B37: Business Personal Property | C37: Removal of Property To Prevent a Loss | E37: X | F37: X | G37: X | H37: X | I37: X | J37: X | K37: X | L37: X | M37: X | N37: X | O37: X
B38: Business Personal Property | C38: Security After Loss | F38: X | G38: X | H38: X | I38: X | J38: X | K38: X | L38: X | M38: X | N38: X | O38: X
B39: Business Personal Property | C39: Property at any Fair, Trade Show or Exhibition | E39: X | F39: X | G39: X | H39: X | I39: X | J39: X | K39: X | L39: X | M39: X | N39: X | O39: X
B40: Business Personal Property | C40: Automated External Defibrillators | I40: X
...

Sheet Question & Observation Log
A1: ID | B1: Question | C1: Response | D1: Meeting Comments | E1: Question For
A2: QU0001 | B2: ISO 2012 - The 2012 ISO Commercial Property product offers coverages that may make certain coverages from the 2007 version obsolete and add new coverages. Is the intent to move to the 2012 ISO Commercial Property Product and what's SECURAs future-state planned product offering? | D2: Additional Consideration: All proprietary coverages & WRAPs would need to be reviewed and potentially replaced with equivalent ISO coverages (eg. "Broadened Business Income" through WRAPs). Duck Creek OOTB uses coverages offered through CP00102012 which , What does the get current with ISO initiative mean in detail (eg. Will we be sunsetting certain ENs, WRAPs, etc.)? Confirm if we are moving to CP00101012 as part of the get current with ISO initiative? | E2: SECURA
A3: QU0002 | B3: BASE COVERAGES - Confirm the future state plan to use ISO Base Coverages - for example: Tobacco Sales & Warehouse, Mortgageholders E&O. | D3: Note: Anything at or below Condo Association Usage (131) | E3: SECURA
A4: QU0003 | B4: PROPRIETARY COVERAGES - See PCM to confirm use of all propriety coverages in future-state
A5: QU0004 | B5: ADDITIONAL COVERAGES - Is SECURA planning to replace the coverages offered today through the Universal WRAPs to individual coverages that can be added as needed to the base coverages? | D5: e.g. coverages offered through universal WRAPs | E5: SECURA
A6: QU0005 | B6: TRADE COVERAGES - What's the future state go to market strategy for trade-specific coverages? Do you want to go to a more standard product as opposed to a bespoke/tailored product to fit your customers needs? | D6: Considerations - Tradeoff between proprietary product offering and a more ISO aligned product. Observation - a lot of the same coverages are present across the WRAPs, if we moved to a componentized model we would need to review and ensure consistent wording. | E6: SECURA
A7: QU0006 | B7: COVERAGE FLEXIBILITY - For future state, assuming there are no system constraints, would SECURA consider the ability to include coverages as needed vs. the current WRAP programs? | D7: Note: A&H has incorporated this model | E7: SECURA
A8: QU0007 | B8: MANDATORY/OPTIONAL - In future-state, assuming we move to a more flexible coverage offering, do we want to make any additional coverages conditionally mandatory based on the customers type of business? | E8: SECURA
A9: QU0008 | B9: INTERNAL - Align on usage of Product and LOB and the potential impacts to coverage, sub-coverage, etc. | D9: Property Products: BPP, Builders Risk, BI and EE, etc. Property LOBs: Commercial Property, Specialty Property, Agri-Business | E9: Rebecca
A10: QU0009 | B10: INTERNAL - Align on definitions of Coverage Effects. | E10: Rebecca
A11: QU0010 | B11: WRAP LIMIT - Is SECURA planning to move to a single Universal WRAP with flex limits (as per discussion in Property Workshop 1)? For example, the concept that's used in the 2 Elite Wraps (250K vs 500K). | E11: SECURA
A12: QU0011 | B12: Do you view the following coverages as: - Ordinance and Law OR A. Demolition Cost B. Coverage of Undamaged Portion of the Building C. Increased Cost of Construction/Increased Period of Restoration -Broadened Business Income vs. BI&EE, Civil Authority, etc. | C12: Ordinance and Law Broadened Biz Income - Keep Granular | E12: SECURA - Claims
A13: QU0012 | B13: For coverages introduced through the Base Form but re-defined through a Wrap, how do you handle claims filed against them? Do you file against the Base Coverage or the Coverage provided, and re-defined, through the WRAP? (e.g., Personal Property of Members, Customers & Guests vs Personal Property of Others - they have individual limits) | C13: Personal Property of Members, Customers & Guests | D13: Filter: Product (Monoline Building & Personal Property), Coverage (Personal Property of Others) | E13: SECURA - Claims
A14: QU0013 | B14: For coverages introduced through a WRAP, how do you handle claims filed against them? (e.g., Theft of Telephone or Dataline Services) Is this filed as a Sub-Coverage (with a sub-limit) of Business Personal Property, or is it filed as a standalone Coverage? | D14: Filter: Product (Monoline Building & Personal Property) Scroll down | E14: SECURA - Claims
A15: QU0014 | B15: For coverages introduced through a Universal WRAP but re-defined through a Trade Wrap, how do you handle claims filed against them? (e.g. Closed Circuit TV Revenue, Patent Infringement Expense Reimbursement). Are these filed as Sub-Coverages of Broadened Business Income (introduced via the Universal Wrap), or are they filed as standalone Coverages? | D15: Filter: Coverages (Broadened Business Income) | E15: SECURA - Claims
A16: QU0015 | B16: Confirm that we are aligned on how we view coverages (see PCM: Building & Personal Property - Building Coverages)

Sheet Product Matrix - Archive
A1: Coverage | B1: Sub-Coverage | C1: Building and Personal Property | D1: Universal Wrap CPT9099 | E1: Inn Wrap CPT 2000 | F1: Human Services Property Wrap NEW - CPT 3500 | G1: Restaurant Wrap CPT 4500 | H1: Contractor and Services Wrap CPT 5500 | I1: Green Industry Contractor Wrap CPT5506 | J1: Manufacturer Wrap CPT 6000
A2: Building | D2: $125,000
B3: Debris Removal | C3: X | D3: Flex Limit (Would Remove for Coverage View)
B4: Electronic Data | C4: X | D4: Flex Limit
B5: Fine Arts At Described Premises | C5: X | D5: Flex Limit
B6: Fire Extinguisher Recharge | C6: X | D6: Flex Limit
B7: Personal Property Of Others (excluding employee tools) | C7: X | D7: Flex Limit
B8: Public Safety Service Charges | D8: Flex Limit
A9: Accounts Receivable (Other Than Electronic Data) On Premises | D9: $25,000
A10: Accounts Receivable (Other Than Electronic Data) Off Premises | D10: X (NEW - $5,000)
A11: Additional Covered Property (Foundations, walks, etc.) | D11: $50,000 (was $10,000)
A12: Additional Covered Property (BPP on structures or in portable units) | D12: NEW - Included in BPP Limit
A13: Broadened Business Income | D13: $25,000 | E13: $50,000 (was $25,000) | J13: $100,000
B14: Civil Authority | D14: Included in BBI Limit | E14: Included in BBI Limit | J14: Included in BBI Limit
B15: Lost Lease Protection | D15: Included in BBI Limit | E15: Included in BBI Limit | J15: Included in BBI Limit
B16: Dependent/Secondary Property Income | D16: Included in BBI Limit | E16: Included in BBI Limit | J16: Included in BBI Limit
B17: Extended Period of Indemnity | D17: NEW - 60 days
A18: Broadened Premises | D18: 1000 feet
A19: BPP - Seasonal Increase | D19: $100,000 or 25% Whichever is Less | I19: 30%
A20: Computer and Funds Transfer Fraud | D20: $5,000 Funds Transfer Fraud Added
A21: Employee Theft | D21: $10,000
A22: Forgery or Alteration (from Office WRAP) | D22: NEW - $25,000
A23: Landlord Furnishings | D23: NEW -Included in Bldg Limit
A24: Lock Replacement due to Theft of Your Keys or Transmitter | D24: $1,000 Deductible dropped from $500 to $0
A25: Money and Securities On | D25: $10,000
A26: Money and Securities Off | D26: $10,000
A27: Money Orders and Counterfeit Money (from Inn WRAP) | D27: NEW - $5,000 | I27: $10,000 (was $5,000)
A28: Newly Acquired Bldg, Cnts, Income (extend # of days to 180) | D28: $1,500,000
A29: Ordinance or Law Undamaged Portion | D29: Included in Bldg Limit
A30: Ord/Law - Tenant Improvements and Betterments | D30: Included in BPP Limit
A31: Ord/Law - Demolition and Inc Costs combined | D31: $100,000
A32: Ord/Law - Increased Period of Restoration | D32: NEW - Included in Broadened Business Income
A33: Outdoor Property - trees/shrubs/plants (limit $1,000 per item) | D33: $10,000 Limit per item increased from $500 | I33: $20,000
A34: Outdoor Property - Fences and Antennas | D34: $10,000
A35: Oudoor Signs - attached or not - limit per sign | D35: $10,000/sign (was $5k/sign)
A36: Personal Effects (Excluding Employee Tools) | D36: $10,000
A37: Property at Fair, Trade Show, or Exhibition | D37: $15,000
A38: Property in a Non-Owned Location | D38: $15,000 | J38: $25,000
A39: Property in Care of a Salesperson | D39: $10,000 (was $5,000)
A40: Property in Transit (Any Vehicle) | D40: $15,000 | J40: $50,000
...

Sheet Product Overview
A1: Product | B1: Does SECURA Offer? | C1: Offered Monoline? | D1: Required Base Coverage
A2: Monoline Building and Personal Property | B2: Yes | C2: Yes | D2: N/A
A3: Monoline Builders Risk | B3: Yes | C3: Yes | D3: N/A
A4: Monoline Business Income (and Extra Expense) | B4: Yes | C4: Yes | D4: N/A
A5: Monoline Condominium Association | B5: Yes | C5: Yes | D5: N/A
A6: Extra Expense | B6: Yes | C6: Follow-Up, Maybe | D6: ? | E6: Example: BPP, BI
A7: Business Income (Without Extra Expense) | B7: Yes | C7: Follow-Up, Maybe | D7: ?
A8: Legal Liability | B8: Yes | C8: Follow-Up, Maybe | D8: ?
A9: Leasehold Interest | B9: Yes | C9: Follow-Up, Maybe | D9: ?
A10: Condo Commercial Unit-Owners | B10: Yes | C10: Follow-Up, leaning Yes | D10: ?
A11: Mortgageholders E&O | B11: Yes | C11: Follow-Up, Maybe | D11: ?
A12: Monoline Tobacco Sales Warehouses | B12: No | C12: No | D12: N/A

Sheet Forms View - MTG
A1: Form Type | B1: Form Number | C1: Product Name | D1: Category | E1: Proprietary or ISO | F1: Count of Forms | G1: PCM? | H1: Owner | I1: Comments | J1: Complete? | Z1: Category | AA1: Prop Or ISO | AB1: PCM?
A3: PR | B3: CP 0090 0788 | C3: COMMERCIAL PROPERTY CONDITIONS | D3: POLICY CONDITIONS | E3: ISO | F3: 30914 | G3: N/A | H3: Tulio | Z3: BASE COVERAGE FORM | AA3: ISO | AB3: N/A
A4: PR | B4: CP 0140 0706 | C4: EXCLUSION OF LOSS DUE TO VIRUS OR BACTERIA | D4: EXCLUSION | E4: ISO | F4: 30914 | G4: N/A | H4: Sal | Z4: OTHER COVERAGE FORM | AA4: Proprietary | AB4: ?
A5: PR | B5: CP 1032 0808 | C5: WATER EXCLUSION ENDORSEMENT | D5: EXCLUSION | E5: ISO | F5: 30913 | G5: N/A | H5: Sal | Z5: ENDORSEMENT | AB5: X
A6: PR | B6: CP 1030 0607 | C6: CAUSES OF LOSS – SPECIAL FORM | D6: EXCLUSION | E6: ISO | F6: 30882 | G6: N/A | Z6: POLICY CONDITIONS
A7: PR | B7: CP 0010 0607 | C7: BUILDING & PERSONAL PROPERTY COVERAGE | D7: BASE COVERAGE FORM | E7: ISO | F7: 30859 | G7: X | H7: Tulio | Z7: CAUSES OF LOSS
A8: PR | B8: CPE 0100 2105 | C8: COMPUTER AMENDATORY | D8: ENDORSEMENT | E8: Proprietary | F8: 30847 | G8: X | H8: Sal | Z8: EXCLUSION
A9: PR | B9: CPE 1075 2105 | C9: EXCLUSION – CYBER INCIDENTS PROPERTY | D9: EXCLUSION | E9: Proprietary | F9: 30847 | G9: ? | H9: Sal | I9: **I believe this grants back: Spoiler Coverage (Power Outage) & Computer Fraud | Z9: OTHER (Notices, Dec, etc.)
A10: PR | B10: CPT 9000 1301 | C10: UNIVERSAL WRAP SCHEDULE | D10: POLICY CONDITIONS | E10: Proprietary | F10: 27599 | G10: N/A | H10: Sal | I10: **Just lists out limits that are being amended | Z10: WRAP
A11: PR | B11: CPT 9099 1301 | C11: UNIVERSAL WRAP COVERAGE FORM | D11: OTHER COVERAGE FORM | E11: Proprietary | F11: 27599 | G11: X | H11: Sal
A12: PR | B12: HSB 5000 1301 | C12: EQUIPMENT BREAKDOWN WRAP CAUSES OF LOSS - BREAKDOWN | D12: OTHER COVERAGE FORM | E12: Proprietary | F12: 27423 | G12: X | H12: Sal
A13: PR | B13: CP 1504 0607 | C13: DISCRETIONARY PAYROLL EXPENSE | D13: POLICY CONDITIONS | E13: ISO | F13: 23128 | G13: X | H13: Sal | I13: **Schedules type of employees/max # of days
A14: PR | B14: CP 0030 0607 | C14: BUSINESS INCOME AND EXTRA EXPENSE COVERAGE | D14: BASE COVERAGE FORM | E14: ISO | F14: 23112 | G14: X | H14: Rohit
A15: PR | B15: CPE 0696 1301 | C15: Water Back-up And Sump Overflow (Not Flood-Related) | D15: OTHER COVERAGE FORM | E15: Proprietary | F15: 20241 | G15: X | H15: Sal
A16: PR | B16: CPE 1555 1301 | C16: BUSINESS INCOME – ACTUAL LOSS SUSTAINED | D16: POLICY CONDITIONS | E16: Proprietary | F16: 18447
A17: PR | B17: CP 1556 0607 | C17: BUSINESS INCOME CHANGES – BEGINNING OF THE PERIOD OF RESTORATION | D17: ENDORSEMENT | E17: ISO | F17: 14730 | G17: N/A | H17: Sal
A18: PR | B18: CPT 5500 1301 | C18: CONTRACTOR AND SERVICES WRAP | D18: OTHER COVERAGE FORM | E18: Proprietary | F18: 9311 | G18: X | H18: Sal
A19: PR | B19: CP 0113 1002 | C19: WISCONSIN CHANGES | D19: ENDORSEMENT | E19: ISO | F19: 8452 | G19: X | H19: Rohit
A20: PR | B20: CP 1550 1185 | C20: RADIO OR TELEVISION ANTENNAS – BUSINESS INCOME OR EXTRA EXPENSE | D20: ENDORSEMENT | E20: ISO | F20: 7819 | G20: N/A | H20: Rohit
A21: PR | B21: CP 1218 0607 | C21: LOSS PAYABLE PROVISIONS | D21: POLICY CONDITIONS | E21: ISO | F21: 6466 | H21: Rohit
A22: PR | B22: CP 0108 0520 | C22: MINNESOTA CHANGES | D22: POLICY CONDITIONS | E22: ISO | F22: 4657
A23: PR | B23: CP 0150 1000 | C23: MINNESOTA CHANGES – REPLACEMENT COST PERSONAL PROPERTY | D23: POLICY CONDITIONS | E23: ISO | F23: 4116
A24: PR | B24: CP 0149 0607 | C24: ILLINOIS CHANGES – ARTIFICIALLY GENERATED ELECTRICAL CURRENT EXCLUSION | D24: EXCLUSION | E24: ISO | F24: 2565 | G24: N/A
A25: PR | B25: CP 0157 0918 | C25: MINNESOTA CHANGES - COINSURANCE | D25: POLICY CONDITIONS | E25: ISO | F25: 2386 | G25: N/A
A26: PR | B26: CP 0128 0700 | C26: MISSOURI – CALCULATION OF ADDITIONAL PREMIUM | D26: ENDORSEMENT | E26: ISO | F26: 2331 | G26: N/A | H26: Tulio
A27: PR | B27: CP 1270 0996 | C27: JOINT OR DISPUTED LOSS AGREEMENT | D27: POLICY CONDITIONS | E27: ISO | F27: 2327 | G27: N/A | H27: Sal | I27: * Requires a CP + Builders' Risk policy by different insurers - describes terms of how a loss to covered property will be payed
A28: PR | B28: CPE 1036 1305 | C28: LIMITATIONS ON COVERAGE FOR ROOF SURFACING | D28: POLICY CONDITIONS | E28: Proprietary | F28: 2278 | G28: N/A | H28: Sal | I28: **This restricts coverage caused by wind/hail to the roof of the building
A29: PR | B29: CP 0166 0900 | C29: KENTUCKY CHANGES | D29: ENDORSEMENT | E29: ISO | F29: 2253 | G29: N/A | H29: Tulio
A30: PR | B30: CP 1040 0899 | C30: EARTHQUAKE AND VOLCANIC ERUPTION ENDORSEMENT | D30: ENDORSEMENT | E30: ISO | F30: 2248 | G30: X | H30: Tulio
A31: PR | B31: CP 0132 0120 | C31: ARIZONA CHANGES | D31: ENDORSEMENT | E31: ISO | F31: 2223 | G31: N/A | H31: Tulio
A32: PR | B32: CP 0146 0894 | C32: ARIZONA CHANGES | D32: ENDORSEMENT | E32: ISO | F32: 2195 | G32: ? | H32: Tulio | I32: This removes Fire Dept. Service Charge… from ALL Property Coverages
A33: PR | B33: CPE 0200 1301 | C33: GREENHOUSE VALUATION AMENDMENT | D33: POLICY CONDITIONS | E33: Proprietary | F33: 2193 | G33: N/A | H33: Sal | I33: **This restricts certain coverage and terms applicable to Greenhouses only (ex: ACV doesn't apply, Coinsurance applies, terms to be covered are added - 'temp must be > 40 degrees)
A34: PR | B34: CPT 7999 1301 | C34: ELITE UNIVERSAL WRAP COVERAGE FORM | D34: OTHER COVERAGE FORM | E34: Proprietary | F34: 1962 | H34: Sal
A35: PR | B35: CP 0120 0421 | C35: MICHIGAN CHANGES | D35: ENDORSEMENT | E35: ISO | F35: 1910 | G35: N/A | H35: Tulio
A36: PR | B36: CPT 7900 1301 | C36: MICHIGAN CHANGES | D36: ENDORSEMENT | E36: Proprietary | F36: 1830 | G36: N/A | H36: Tulio | I36: This is just a schedule for the Michigan Wrapper
A37: PR | B37: CPE 2411 1106 | C37: MISSOURI CHANGES – LOSS NOTICE REQUIREMENTS | D37: OTHER (Notices, Dec, etc.) | E37: Proprietary | F37: 1823 | G37: N/A
A38: PR | B38: CP 1221 0208 | C38: LOSS PAYABLE PROVISIONS - MINNESOTA | D38: POLICY CONDITIONS | E38: ISO | F38: 1451 | G38: N/A
A39: PR | B39: CP 0114 1115 | C39: NORTH DAKOTA CHANGES | D39: ENDORSEMENT | E39: ISO | F39: 1400 | G39: N/A | H39: Tulio | I39: Valued Policies 2. might be good to double check with Rebecca
A40: PR | B40: CPT 4500 1301 | C40: RESTAURANT WRAP | D40: WRAP | E40: Proprietary | F40: 1291 | G40: X | H40: Sal
A41: PR | B41: CP 0152 0796 | C41: INDIANA CHANGES – RIGHTS OF RECOVERY | D41: ENDORSEMENT | E41: ISO | F41: 1200 | G41: N/A | H41: Tulio
...

Sheet Temporary - TODO & Status
A1: Item | B1: Owner | C1: Status | F1: Draft but Row is Complete
A2: CP0010 - ISO in PCM | B2: Tulio | C2: Complete | F2: Internally Reviewed
A3: CP0020, 0030 (Core Form Amendments) - in PCM | B3: Tulio | C3: Complete | F3: Question for Rebecca
A4: Duck Creek Forms Inventory XLS | B4: Rohit | C4: Complete | F4: Need Client Input/Suggestions
A5: Duck Creek Forms Extract PDF | B5: Rohit | C5: Complete | F5: Ready for Client Discussion
A6: Endorsement Coverage Forms | B6: Sal | C6: In Progress

Sheet Ref Connect Pull
A1: LOB | B1: ISO / SECURA | C1: SECURA PSR# | D1: Form Number | F1: Title | G1: State | H1: 08 11 Changes | I1: Adoption Date | J1: Expired | K1: Rule # | L1: Blocked ISO Rule | M1: CoverAll Not Supported | N1: Static / Variable | O1: Default | P1: Override Type | Q1: ISO Schedule | R1: Supplemental Declaration | S1: Static/Variable | T1: Auto Attach VS Manual Attach | U1: PW Product Screen Entry | V1: Form Tab Manual Screen Entry | W1: Addl Interest | X1: Base Form Attachment Criteria | Y1: SECURA Customization | Z1: Testing Notes | AA1: Property Dec Print- Optional Coverages and Policy Optional Coverages sections | AB1: Coverage Form Trigger | AC1: Turn Off/ Customization | AD1: CoverAll does not support | AE1: Circular | AF1: Filing ID | AG1: ISO Footnote | AH1: Not On CoverAll List | AI1: Form Number | AJ1: Topic (from Master Test List) JE | AK1: Customize (from Master Test List) JE | AM1: Covered in Regression (Y/N) | AN1: Sample Regression Name | AO1: Transaction Name
A2: All | B2: SECURA | C2: RQ-734 | D2: ALD 0001 1204 | E2: =VLOOKUP(LOWER(TRIM(D2)),'Property Forms Usage'!#REF!,1,0) -> #REF! | F2: COMMON POLICY DECLARATIONS | I2: 41654 | S2: Variable | Y2: Defaults on the policy when renewal rewards, account credit, an association or program factor or commission change applies to the policy.
A3: All | B3: SECURA | D3: ALD 9999 0711 | E3: =VLOOKUP(LOWER(TRIM(D3)),'Property Forms Usage'!#REF!,1,0) -> #REF! | F3: OFFICER SIGNATURE PAGE | I3: 44738 | S3: Variable | Y3: Attaches to all policies.
A4: PR | B4: SECURA | C4: 71128 | D4: AGP 0184 1001 | E4: =VLOOKUP(LOWER(TRIM(D4)),'Property Forms Usage'!#REF!,1,0) -> #REF! | F4: Waiver Of Deductible - Commodities | I4: 41640 | N4: System Variable | P4: Both | Q4: Yes | R4: No | S4: Variable | T4: Manual | V4: yes | W4: N | Y4: Form should be available for manual selection when the Market Segment = Agribusiness.
A5: PR | B5: ISO | C5: 61780 | D5: CP00100607 | E5: =VLOOKUP(LOWER(TRIM(D5)),'Property Forms Usage'!#REF!,1,0) -> #REF! | F5: Building And Personal Proerty Coverage Form | I5: 41275 | K5: 14ex 30 31 32 35 36 38 68 70 71 | L5: 69 | N5: Static | Q5: No | R5: No | S5: Static | T5: Automatic | V5: n/a | X5: Loc Bldg screen/ Property Coverages section/ select Building Coverage -AND/OR- select Personal Property Coverage/ select Business Personal Property, Personal Property Of Others Coverage, or Condominium Commercial Unit-Owners Coverage | Y5: CPE 0018 along with CP0010 replace CP0018. | AB5: n/a | AE5: LI-CF-2008-059 | AF5: CF-2007-OFR07 | AJ5: ISO Exception Rule 69 - AZ KS MN MO PA
A6: PR | B6: ISO | D6: CP00170607 | E6: =VLOOKUP(LOWER(TRIM(D6)),'Property Forms Usage'!#REF!,1,0) -> #REF! | F6: Condominium Association Coverage Form | I6: 39813 | K6: 14 30 31 38 | L6: 69 | N6: Static | S6: Static | T6: Automatic | V6: n/a | X6: bldg cov screen/select "condominium association" as coverage | AB6: n/a | AE6: LI-CF-2008-059 | AF6: CF-2007-OFR07
A7: PR | B7: ISO | C7: 61780 | D7: CP00180607 | E7: =VLOOKUP(LOWER(TRIM(D7)),'Property Forms Usage'!#REF!,1,0) -> #REF! | F7: Condominium Commercial Unit-Owners Coverage Form | I7: 41275 | K7: 14ex 31 35 36 37 38 | N7: Static | S7: Static | T7: Automatic | V7: n/a | X7: Loc Bldg/ Personal Property Coverage screen - Coverage Type section/ Personal Property Coverage Options = Condominium Commercial Unit-Owners Coverage | Y7: CPE 0018 along with CP0010 replace CP0018. | Z7: SECURA Customization - SECURA will use CPE 0018 and CP 0010 in place of CP 0018. See Defaults Customization - Working as Expected | AB7: n/a | AE7: LI-CF-2008-059 | AF7: CF-2007-OFR07
A8: PR | B8: ISO | D8: CP00200607 | E8: =VLOOKUP(LOWER(TRIM(D8)),'Property Forms Usage'!#REF!,1,0) -> #REF! | F8: Builders Risk Coverage Form | I8: 39813 | K8: 38 40 41 | N8: Static | S8: Static | T8: Automatic | V8: n/a | X8: loc screen/class code = 1150 | AB8: n/a | AE8: LI-CF-2008-059 | AF8: CF-2007-OFR07
A9: PR | B9: ISO | D9: CP00300607 | E9: =VLOOKUP(LOWER(TRIM(D9)),'Property Forms Usage'!#REF!,1,0) -> #REF! | F9: Business Income (And Extra Expense) Coverage Form | I9: 39813 | K9: 50 51 54 A2 | N9: Static | Q9: No | R9: No | S9: Static | T9: Automatic | V9: n/a | X9: Loc Bldg screen/ Property Coverages Section/ select Business Income// Business Income screen/ Coverage Information section/ Coverage Form = And Extra Expense | AB9: n/a | AE9: LI-CF-2008-059 | AF9: CF-2007-OFR07
A10: PR | B10: ISO | D10: CP00320607 | E10: =VLOOKUP(LOWER(TRIM(D10)),'Property Forms Usage'!#REF!,1,0) -> #REF! | F10: Business Income (Without Extra Expense) Coverage Form | I10: 39813 | K10: 50 51 54 A1 | N10: Static | S10: Static | T10: Automatic | V10: n/a | X10: loc screen/select Business Income/On business income screen the coverage form = without Extra Expense | AB10: n/a | AE10: LI-CF-2008-059 | AF10: CF-2007-OFR07
A11: PR | B11: ISO | D11: CP00400607 | E11: =VLOOKUP(LOWER(TRIM(D11)),'Property Forms Usage'!#REF!,1,0) -> #REF! | F11: Legal Liability Coverage Form | I11: 39813 | K11: 66 72 | N11: Static | S11: Static | T11: Automatic | V11: n/a | X11: Bldg screen/Building Coverage/Coverage (Building defaults)/select Legal Liability and/or BPP screen/Personal Property Coverage Options/select Legal Liability Coverage radio button | AB11: n/a | AE11: LI-CF-2008-059 | AF11: CF-2007-OFR07
A12: PR | B12: ISO | D12: CP00500607 | E12: =VLOOKUP(LOWER(TRIM(D12)),'Property Forms Usage'!#REF!,1,0) -> #REF! | F12: Extra Expense Coverage Form | I12: 39813 | K12: 52 53 A1 | L12: 53.B.5 | N12: Static | S12: Static | T12: Automatic | V12: n/a | X12: loc screen/Extra Expense, then complete new screen | AB12: n/a | AE12: LI-CF-2008-059 | AF12: CF-2007-OFR07
A13: PR | B13: ISO | D13: CP00600695 | E13: =VLOOKUP(LOWER(TRIM(D13)),'Property Forms Usage'!#REF!,1,0) -> #REF! | F13: Leasehold Interest Coverage Form | I13: 39813 | K13: 32 65 | N13: Static | S13: Static | T13: Automatic | V13: n/a | X13: Bldg Screen - drop down for Covg Info - choose Leasehold - fill out several other boxes | AB13: n/a | AG13: (2)
A14: PR | B14: ISO | D14: CP00700607 | E14: =VLOOKUP(LOWER(TRIM(D14)),'Property Forms Usage'!#REF!,1,0) -> #REF! | F14: Mortgageholders Errors And Omissions Coverage Form | I14: 39813 | K14: 14 38 67 | N14: Static | S14: Static | T14: Automatic | V14: n/a | X14: loc screen/mortgageholders e&o, then complete new screen | AB14: n/a | AE14: LI-CF-2008-059 | AF14: CF-2007-OFR07
A15: PR | B15: ISO | D15: CP00800607 | E15: =VLOOKUP(LOWER(TRIM(D15)),'Property Forms Usage'!#REF!,1,0) -> #REF! | F15: Tobacco Sales Warehouses Coverage Form | I15: 39813 | K15: 14ex 38 | L15: 68 | N15: Static | S15: Static | T15: Automatic | V15: n/a | X15: loc screen/tobacco sales warehouses coverage, then complete new screen | Z15: blocking rule | AB15: n/a | AE15: LI-CF-2008-059 | AF15: CF-2007-OFR07
A16: PR | B16: ISO | D16: CP00900788 | E16: =VLOOKUP(LOWER(TRIM(D16)),'Property Forms Usage'!#REF!,1,0) -> #REF! | F16: Commercial Property Conditions | I16: 39813 | K16: 14 67 | L16: 69 | N16: Static | Q16: No | R16: No | S16: Static | T16: Automatic | V16: n/a | X16: Mandatory | Z16: this form is not applicable when CP0070 is on policy | AB16: n/a | AE16: CF-88-68 | AG16: (2)
A17: PR | B17: ISO | D17: CP00990607 | E17: =VLOOKUP(LOWER(TRIM(D17)),'Property Forms Usage'!#REF!,1,0) -> #REF! | F17: Standard Property Policy | G17: Not KS | I17: 39813 | K17: 14 14ex 31 38 | L17: 69 | N17: Static | S17: Static | T17: Automatic | V17: n/a | X17: comml prop screen- standard prop pol checkbox | Z17: blocking rule | AB17: n/a | AE17: LI-CF-2008-059 | AF17: CF-2007-OFR07 | AJ17: ISO Exception Rule 69 - AZ KS MN MO PA
A18: PR | B18: ISO | D18: CP01010105 | E18: =VLOOKUP(LOWER(TRIM(D18)),'Property Forms Usage'!#REF!,1,0) -> #REF! | F18: Kansas Changes | G18: KS | I18: 38353 | J18: 40909 | K18: 14ex 30ex | N18: Static | S18: Static | T18: Automatic | V18: n/a | X18: Attach when State = KS | AB18: Commercial Property Coverage Part | AE18: LI-CL-2004-068 | AF18: CL-2004-OEND1
A19: PR | B19: ISO | D19: CP01010112 | E19: =VLOOKUP(LOWER(TRIM(D19)),'Property Forms Usage'!#REF!,1,0) -> #REF! | F19: Kansas Changes | G19: KS | I19: 40909 | J19: 43952 | S19: Static
A20: PR | B20: ISO | D20: CP01010619 | E20: =VLOOKUP(LOWER(TRIM(D20)),'Property Forms Usage'!#REF!,1,0) -> #REF! | F20: Kansas Changes | G20: KS | I20: 43952 | K20: 14ex 30ex | N20: Static | S20: Static | T20: Automatic | V20: n/a | X20: Attach when State = KS | AB20: Commercial Property Coverage Part | AE20: LI-CL-2004-068 | AF20: CL-2004-OEND1
A21: PR | B21: ISO | D21: CP01060896 | E21: =VLOOKUP(LOWER(TRIM(D21)),'Property Forms Usage'!#REF!,1,0) -> #REF! | F21: Minnesota Changes - Condominiums | G21: MN | I21: 35278 | K21: 14ex | N21: Static | S21: Static | T21: Automatic | V21: n/a | X21: Attach when State = MN and Condominium class code | AB21: Condominium Association Coverage Form
A22: PR | B22: ISO | D22: CP01070695 | E22: =VLOOKUP(LOWER(TRIM(D22)),'Property Forms Usage'!#REF!,1,0) -> #REF! | F22: Condominium Additional Provisions | G22: AZ MO PA | I22: 39813 | K22: 14 14ex | N22: Static | S22: Static | T22: Automatic | V22: n/a | X22: Attach when State = AZ MO or PA. Must be condo association and on bldg screen select checkbox "created after 19xx…" | AB22: Condominium Association Coverage Form
A23: PR | B23: ISO | D23: CP01080208 | E23: =VLOOKUP(LOWER(TRIM(D23)),'Property Forms Usage'!#REF!,1,0) -> #REF! | F23: Minnesota Changes | G23: MN | I23: 39479 | J23: 43952 | K23: 14ex | N23: Static | S23: Static | T23: Automatic | V23: n/a | X23: Attach when State = MN | AB23: Commercial Property Coverage Part | AE23: LI-CF-2008-118 | AF23: CF-2007-OFR07
A24: PR | B24: ISO | C24: 48565/RQ-1338 | D24: CP01080520 | E24: =VLOOKUP(LOWER(TRIM(D24)),'Property Forms Usage'!#REF!,1,0) -> #REF! | F24: Minnesota Changes | G24: MN | I24: 43952 | K24: 14ex | N24: Static | S24: Static | T24: Automatic | V24: n/a | X24: Attach when State = MN | AB24: Commercial Property Coverage Part | AE24: LI-CF-2008-118 | AF24: CF-2007-OFR07
