Workbook
Name Bureau: 'Data Validation'!$H$5:$H$7
Name Complexity: 'Headers & Footers'!#REF!
Name Complexity: #REF!
Name CPT6022KSPR: 'Dynamic Data'!#REF!
Name CPT6022KSPRODUCTRECALL: 'Dynamic Data'!#REF!
Name FormCP: 'Headers & Footers'!$A$10
Name FormCP1: 'Headers & Footers'!$A$10
Name Open: 'Headers & Footers'!#REF!
Name Open: #REF!
Name Proprietary: 'Data Validation'!$G$5:$G$6
Name Requirementstatus: 'Headers & Footers'!#REF!
Name Requirementstatus: #REF!
Name Status: 'Headers & Footers'!#REF!
Name Status: #REF!
Name Usage: '[1]Data Validation'!#REF!
Name Usage: 'Data Validation'!$F$5:$F$6

Sheet Revision History
A1: REVISION HISTORY
A2: Client: | B2: <Client Name> Insurance Companies
A3: Phase: | B3: Product Simplification
C4: COLUMN | D4: DEFINITION
C5: Reference ID | D5: Reference any changes made with the subsequent PCM ID.
C6: PCM Framework ID | D6: Enter PCM Framework ID for form updated. If multiple changes or no change specific to form use N/A.
C7: Date of Change | D7: Date of change in MM/DD/YYYY format.
C8: Description & Justification of Change | D8: Use this column to describe the change made. Use detail. Describe the business need to make the change.
C9: Person Making Change | D9: Enter your full name.
A11: REFERENCE ID | B11: PCM FRAMEWORK ID | C11: DATE OF CHANGE | D11: DESCRIPTION & JUSTIFICATION OF CHANGE | E11: PERSON MAKING CHANGE

Sheet SOP
A1: Standard Operating Procedures - Forms Library
A2: Client: | B2: <Client Name> Insurance Companies
A3: Phase: | B3: Product Simplification
A5: 1. Intent of spreadsheet
A6: 2. Users of the spreadsheet
A7: 3. Examples of how the sheet can be used to meet business needs
A8: 4. A place to document our process while working through this spreadsheet and other spreadsheets (so that this process can be easily repeatable when we roll out other lines)
A10: Example of this is: Fill out the Forms Library at a high level of what you know at a quick look. Then later on when you are working on the associated rule (if there is one) once you’ve completed the rule, refer back to the Forms Library to verify if the information on that spreadsheet is still accurate and update as needed. We may find out as we are working on a rule that there are additional rules or logic associated with it, or we may decide to add some along the way and we want to make sure to back track to update the Forms Library accordingly.
A11: Another example to document would be how we are handling forms and associated rules that are blocked. For the form attachment conditions we talked and decided that we would not worry with spelling out additional attachment logic at this time for forms that are blocked. Example would be CG 0122. Rule 48 for Products/Completed Operations Liability Coverage is rule that would be blocked because we are not writing this product. There is however a condition of the form attaching within this rule but we’ve decided at this time we will not worry about spelling that out because if in the future we do decide to write this product we’ll need to be doing an in-depth review of the entire product anyways. Additionally the rule could change between now and then and we would be maintaining a product that we may never use. (We are aware that in the meeting it sounded like a decision had been made that we will be writing this product, but we are circling back around with Jeri on this. So for the purpose of this email this is purely just an example.)

Sheet Definitions
A1: COLUMN DEFINITIONS - FORMS LIBRARY | D1: Forms Library Color Legend
A2: Client: | B2: <Client Name> Insurance Companies | D2: Grey | E2: Coverage will not be used and no replacement form
A3: Phase: | B3: Product Simplification | D3: Blue | E3: ISO form replaced by <Client Name> form
A4: COLUMN NAME | B4: DEFINITION
A5: Product Framework ID | B5: This is the same as the ID from the Product Component Model (PCM) document
A6: LOB | B6: A Line of Business (LOB) is a specific Product, which contains a group of related Coverages
A7: Coverage | B7: Coverage is the scope of protection against a specific loss or liability within a Line of Business
A8: Sub Coverage | B8: Sub-Coverage is the scope of protection against a specific loss or liability, and has a parent-child relationship with a Coverage. Often times offered as supplementary or optional for additional premium
A9: Form Name | B9: The Title on the Form
A10: Form Number | B10: The Number of the Form
A11: Form Edition Date | B11: Date of the most current version of a form (in MMYY format for ISO and client)
A12: Form Effective Date | B12: This is the Form Effective Date.
A13: Form Expiration Date | B13: This is the Form Expiration Date. (12/31/9999 identifies there is no expiration date)
A14: Bureau | B14: This column indicates the applicability/non-applicability of bureau forms. ISO - indicates a selection of ISO bureau form. Accord - indicates a selection of an Accord form AAIS - indicates a selection of AAIS bureau form. NCCI - indicates a selection of NCCI form N/A - indicates a selected form is not a bureau form
A15: Proprietary | B15: This column indicates if the forms is specific to <Client Name> or a bureau forms. Yes - indicates a form is a proprietary form. No - indicates a form is a non-proprietary form
... A38: UI Trigger | B38: Form is triggered by workflow
A40: COLUMN DEFINITIONS - FORM MERGED FIELDS
A41: COLUMN NAME | B41: DEFINITION
A42: Form No. | B42: The Number of the Form
A43: Form Name | B43: The Title on the Form
A44: Dynamic Field Name | B44: This is the field on the form where data will be mapped to from the policy
A45: Data Type | B45: Preferred format for a field e.g. Date field mask is mm/dd/yyyy
A46: Condition/Rule | B46: This is the rule that governs when the merged field is populated with policy data
A47: Iterative | B47: If the field is dynamic and repeats multiple times Yes: field repeats on the form No: field does not repeat
A48: EFFECTIVE DATE OF DYNAMIC FIELD | B48: Effective date for the dynamic data field
A49: EXPIRATION DATE OF DYNAMIC FIELD | B49: Expiration date for the dynamic data field
A50: UI Field ID | B50: This is the field in the user interface which has the data to be mapped into the merged field
A51: UI Caption | B51: This is the actual name of the user interface field
A52: Field Xpath | B52: This is the Duck Creek location of the field
... A67: Cancel | B67: The Cancel transaction cancels a policy and sets the policy status to Cancelled.
G100: LOB | H100: # of Forms with Status "Not Started" | I100: # of Forms with Status "Ready for Review-Draft" | J100: # of Forms with Status "Business Review-In Progress" | K100: # of Forms with Status "Approved-Completed"
G101: GL | H101: =COUNTIF('Forms Library'!#REF!, "Not Started") -> #REF! | I101: =COUNTIF('Forms Library'!#REF!, "Ready for Review - Draft") -> #REF! | J101: =COUNTIF('Forms Library'!#REF!, "Business Review - In Progress") -> #REF! | K101: =COUNTIF('Forms Library'!#REF!, "Approved - Completed") -> #REF!

Sheet Forms Library
A1: FORMS LIBRARY - GENERAL LIABILITY
A2: Client: | B2: <Client Name>
A3: Phase: | B3: <Placeholder>
B4: FORMS DETAILS | Q4: PRODUCT | AA4: STATE APPLICABILITY | CA4: FORM CONDITIONS | CE4: TRANSACTIONS
A5: PRODUCT FRAMEWORK ID | B5: FORM NAME | C5: FORM NUMBER | D5: FORM EDITION DATE (MMYY - ISO and PROPRIETARY) | E5: FORM EFFECTIVE DATE | F5: FORM EXPIRATION DATE | G5: BUREAU | H5: PROPRIETARY | I5: ADMITTED / NOT ADMITTED | J5: FORM CATEGORY | K5: DYNAMIC / STATIC | L5: DYNAMIC DATA | M5: PREMIUM BEARING | N5: MARKET SEGMENT #1 | O5: MARKET SEGMENT #2 | P5: MARKET SEGMENT #2 | Q5: COMMERCIAL GENERAL LIABILITY | R5: OWNERS AND CONTRACTORS PROTECTIVE LIABILITY | S5: RAILROAD PROTECTIVE LIABILITY | T5: PRODUCTS/ COMPLETED OPERATIONS LIABILITY | U5: ELECTRONIC DATA LIABILITY | V5: POLLUTION LIABILITY | W5: LIQUOR LIABILITY | X5: UNDERGROUND STORAGE TANKS | Y5: PRODUCT WITHDRAWAL | Z5: ALL STATES | AA5: AL | AB5: AK | AC5: AZ | AD5: AR | AE5: CA | AF5: CO | AG5: CT | AH5: DC | AI5: DE | AJ5: FL | AK5: GA | AL5: HI | AM5: ID | AN5: IL | AO5: IN | AP5: IA | AQ5: KS | AR5: KY | AS5: LA | AT5: ME | AU5: MD | AV5: MA | AW5: MI | AX5: MN | AY5: MS | AZ5: MS | BA5: MO | BB5: MT | BC5: NE | BD5: NV | BE5: NH | BF5: NJ | BG5: NM | BH5: NY | BI5: NC | BJ5: ND | BK5: OH | BL5: OK | BM5: OR | BN5: PA | BO5: RI | BP5: SC | BQ5: SD | BR5: TN | BS5: TX | BT5: UT | BU5: VT | BV5: VA | BW5: WA | BX5: WV | BY5: WI | BZ5: WY | CA5: MANDATORY / OPTIONAL / CONDITIONAL | CB5: ATTACHMENT CONDITIONS | CC5: DISPLAY ON FORMS SCHEDULE | CD5: SINGLE OR MULTI-USE | CE5: Quote | CF5: Bind | CG5: New Business | CH5: Endorse | CI5: Rewrite | CJ5: Reissue | CK5: Renew | CL5: Non-Renew | CM5: Reinstate | CN5: Final Audit | CO5: Cancel pending | CP5: Cancel
B6: COMMERCIAL GENERAL LIABILITY COVERAGE FORM | C6: CG 00 01 | D6: 413 | E6: 41365 | F6: 2958465 | G6: ISO | H6: No | I6: Admitted | J6: Base Coverage Form | K6: Static | L6: N/A | M6: Yes | Q6: X | CA6: Mandatory | CB6: No additional conditions | CC6: Yes | CD6: SINGLE
B7: COMMERCIAL GENERAL LIABILITY COVERAGE FORM | C7: CG 00 02 | D7: 413 | E7: 41365 | F7: 2958465 | G7: ISO | H7: No | I7: Admitted | J7: Base Coverage Form | K7: Static | L7: N/A | M7: Yes | Q7: X | CA7: Mandatory | CB7: When Claims Basis is Claims Made | CC7: Yes | CD7: SINGLE
B8: OWNERS AND CONTRACTORS PROTECTIVE LIABILITY COVERAGE FORM - COVERAGE FOR OPERATIONS OF DESIGNATED CONTRACTOR | C8: CG 00 09 | D8: 413 | E8: 4/1/2013 | F8: 2958465 | G8: ISO | H8: No | I8: Admitted | J8: Base Coverage Form | K8: Static | L8: N/A | M8: Yes | R8: X | T8: X | CA8: Mandatory | CB8: No additional conditions | CC8: Yes | CD8: SINGLE
B9: LIQUOR LIABILITY COVERAGE FORM | C9: CG 00 33 | D9: 413 | E9: 4/1/2013 | F9: 2958465 | G9: ISO | H9: No | I9: Admitted | J9: Base Coverage Form | K9: Static | L9: N/A | M9: Yes | W9: X | CA9: Mandatory | CB9: No additional conditions | CC9: Yes | CD9: SINGLE
B10: LIQUOR LIABILITY COVERAGE FORM | C10: CG 00 34 | D10: 413 | E10: 4/1/2013 | F10: 2958465 | G10: ISO | H10: No | I10: Admitted | J10: Base Coverage Form | K10: Static | L10: N/A | M10: Yes | W10: X | CA10: Mandatory | CB10: When Claims Basis is Claims Made | CC10: Yes | CD10: SINGLE
B11: RAILROAD PROTECTIVE LIABILITY COVERAGE FORM | C11: CG 00 35 | D11: 413 | E11: 4/1/2013 | F11: 2958465 | G11: ISO | H11: No | I11: Admitted | J11: Base Coverage Form | K11: Static | L11: N/A | M11: Yes | S11: X | CA11: Mandatory | CB11: No additional conditions | CC11: Yes | CD11: SINGLE
B12: PRODUCTS/COMPLETED OPERATIONS LIABILITY COVERAGE FORM | C12: CG 00 37 | D12: 413 | E12: 4/1/2013 | F12: 2958465 | G12: ISO | H12: No | I12: Admitted | J12: Base Coverage Form | K12: Static | L12: N/A | M12: Yes | T12: X | CA12: Mandatory | CB12: When Claims basis is Occurrence | CC12: Yes | CD12: SINGLE
B13: PRODUCTS/COMPLETED OPERATIONS LIABILITY COVERAGE FORM | C13: CG 00 38 | D13: 413 | E13: 4/1/2013 | F13: 2958465 | G13: ISO | H13: No | I13: Admitted | J13: Base Coverage Form | K13: Static | L13: N/A | M13: Yes | T13: X | CA13: Mandatory | CB13: When Claims Basis is Claims Made | CC13: Yes | CD13: SINGLE
B14: POLLUTION LIABILITY COVERAGE FORM DESIGNATED SITES | C14: CG 00 39 | D14: 413 | E14: 4/1/2013 | F14: 2958465 | G14: ISO | H14: No | I14: Admitted | J14: Base Coverage Form | K14: Static | L14: N/A | M14: Yes | V14: X | CA14: Mandatory | CB14: When Claims Basis is Claims Made | CC14: Yes | CD14: SINGLE
B15: POLLUTION LIABILITY LIMITED COVERAGE FORM DESIGNATED SITES | C15: CG 00 40 | D15: 413 | E15: 4/1/2013 | F15: 2958465 | G15: ISO | H15: No | I15: Admitted | J15: Base Coverage Form | K15: Static | L15: N/A | M15: Yes | V15: X | CA15: Mandatory | CB15: When Pollution type is limited and Claims basis is Claims Made | CC15: Yes | CD15: SINGLE
B16: UNDERGROUND STORAGE TANK POLICY DESIGNATED TANKS | C16: CG 00 42 | D16: 413 | E16: 4/1/2013 | F16: 2958465 | G16: ISO | H16: No | I16: Admitted | J16: Base Coverage Form | K16: Static | L16: N/A | M16: Yes | X16: X | CA16: Mandatory | CB16: When Claims Basis is Claims Made | CC16: Yes | CD16: SINGLE
B17: ELECTRONIC DATA LIABILITY COVERAGE FORM | C17: CG 00 65 | D17: 413 | E17: 4/1/2013 | F17: 2958465 | G17: ISO | H17: No | I17: Admitted | J17: Base Coverage Form | K17: Static | L17: N/A | M17: Yes | U17: X | CA17: Mandatory | CB17: When Claims Basis is Claims Made | CC17: Yes | CD17: SINGLE
B18: PRODUCT WITHDRAWAL COVERAGE FORM | C18: CG 00 66 | D18: 413 | E18: 4/1/2013 | F18: 2958465 | G18: ISO | H18: No | I18: Admitted | J18: Base Coverage Form | K18: Static | L18: N/A | M18: Yes | Y18: X | CA18: Mandatory | CB18: No additional conditions | CC18: Yes | CD18: SINGLE
B19: CHANGES IN GENERAL LIABILITY FORMS FOR COMMERCIAL PACKAGE POLICIES | C19: CG 00 99 | D19: 1185 | E19: 2/1/1986 | F19: 2958465 | G19: ISO | H19: No | I19: Admitted | J19: Base Coverage Form | K19: Static | L19: N/A | M19: No | Q19: X | R19: X | T19: X | CA19: Optional | CB19: When Packaged Policy is created | CC19: Yes | CD19: SINGLE
B20: KANSAS AND OKLAHOMA CHANGES - TRANSFER OF RIGHTS | C20: CG 01 09 | D20: 1185 | E20: 2/1/1986 | F20: 2958465 | G20: ISO | H20: No | I20: Admitted | J20: Endorsement | K20: Static | L20: N/A | M20: No | Q20: X | CA20: Mandatory | CB20: No additional conditions | CC20: Yes | CD20: SINGLE
B21: PENNSYLVANIA CHANGES IN COMMERCIAL GENERAL LIABILITY COVERAGE FORM - INSURING AGREEMENT | C21: CG 01 10 | D21: 894 | E21: 9/1/1994 | F21: 2958465 | G21: ISO | H21: No | I21: Admitted | J21: Policy Notice | K21: Static | L21: N/A | M21: No | Q21: X | CA21: Mandatory | CB21: When Claims Basis is Claims Made | CC21: Yes | CD21: SINGLE
B22: PENNSYLVANIA CHANGES IN PRODUCTS/COMPLETED OPERATIONS LIABILITY COVERAGE FORM - INSURING AGREEMENT | C22: CG 01 11 | D22: 894 | E22: 9/1/1994 | F22: 2958465 | G22: ISO | H22: No | I22: Admitted | J22: Policy Notice | K22: Static | L22: N/A | M22: No | T22: X | CA22: Mandatory | CB22: When Claims Basis is Claims Made | CC22: Yes | CD22: SINGLE
B23: MINNESOTA CHANGES - UNIT-OWNERS OF TOWNHOUSE OR HOMEOWNER ASSOCIATIONS | C23: CG 01 20 | D23: 1219 | E23: 12/1/2019 | F23: 2958465 | G23: ISO | H23: No | I23: Admitted | J23: Policy Notice | K23: Static | L23: N/A | M23: No | Q23: X | CA23: Optional | CB23: Defined by Rule | CC23: Yes | CD23: SINGLE
B24: MINNESOTA CHANGES-CONTRACTUAL LIAB EXCL AND SUPP PAYMENTS | C24: CG 01 22 | D24: 1207 | E24: 12/1/2007 | F24: 2958465 | G24: ISO | H24: No | I24: Admitted | J24: Endorsement | K24: Static | L24: N/A | M24: No | Q24: X | R24: X | T24: X | CA24: Conditional | CB24: Mandatory when Product equals Commercial General Liability or Owners And Contractors Protective Liability When Product equals Products/Completed Operations Liability - Mandatory defined by rule | CC24: Yes | CD24: SINGLE
B25: INDIANA CHANGES POLLUTION EXCLUSION | C25: CG 01 23 | D25: 397 | E25: 3/1/1997 | F25: 2958465 | G25: ISO | H25: No | I25: Admitted | J25: Exclusion | K25: Static | L25: N/A | M25: No | Q25: X | CA25: Optional | CB25: Defined by Rule | CC25: Yes | CD25: SINGLE
B26: WISCONSIN CHANGES - AMENDMENT OF POLICY CONDITIONS | C26: CG 01 24 | D26: 193 | E26: 12/1/1993 | F26: 2958465 | G26: ISO | H26: No | I26: Admitted | J26: Endorsement | K26: Static | L26: N/A | M26: No | Q26: X | T26: X | V26: X | W26: X | CA26: Mandatory | CB26: No additional conditions | CC26: Yes | CD26: SINGLE
B27: CONDOMINIUMS | C27: CG 01 27 | D27: 1185 | E27: 2/1/1986 | F27: 2958465 | G27: ISO | H27: No | I27: Admitted | J27: Endorsement | K27: Static | L27: N/A | M27: No | Q27: X | CA27: Optional | CB27: Defined by Rule Else Selectable | CC27: Yes | CD27: SINGLE
B28: MINNESOTA CHANGES-CONDOMINIUMS | C28: CG 01 28 | D28: 798 | E28: 4/1/1999 | F28: 2958465 | G28: ISO | H28: No | I28: Admitted | J28: Endorsement | K28: Static | L28: N/A | M28: No | Q28: X | CA28: Optional | CB28: Defined by Rule | CC28: Yes | CD28: SINGLE
B29: MISSOURI CHANGES-POLLUTION EXCLUSION | C29: CG 01 34 | D29: 803 | E29: 8/1/2003 | F29: 2958465 | G29: ISO | H29: No | I29: Admitted | J29: Exclusion | K29: Static | L29: N/A | M29: No | Q29: X | V29: X | CA29: Optional | CB29: Defined by Rule | CC29: Yes | CD29: SINGLE
B30: MISSOURI CHANGES-GASOLINE RISKS-POLLUTION EXCLUSION | C30: CG 01 35 | D30: 803 | E30: 8/1/2003 | F30: 2958465 | G30: ISO | H30: No | I30: Admitted | J30: Exclusion | K30: Static | L30: N/A | M30: No | Q30: X | CA30: Optional | CB30: Defined by Rule | CC30: Yes | CD30: SINGLE
B31: UTAH CHANGES - COMMON-INTEREST ASSOCIATIONS | C31: CG 01 47 | D31: 1113 | E31: 41579 | F31: 2958465 | G31: ISO | H31: No | I31: Admitted | J31: Endorsement | K31: Static | L31: N/A | M31: No | Q31: X | CA31: Optional | CB31: Selectable | CC31: Yes | CD31: SINGLE
B32: KENTUCKY CHANGES - SURFACE COAL MINING OPERATIONS | C32: CG 01 48 | D32: 613 | E32: 6/1/2013 | F32: 2958465 | G32: ISO | H32: No | I32: Admitted | J32: Endorsement | K32: Static | L32: N/A | M32: No | Q32: X | CA32: Optional | CB32: Defined by Rule | CC32: Yes | CD32: SINGLE
B33: ILLINOIS CHANGES - CONDOMINIUMS | C33: CG 01 65 | D33: 805 | E33: 8/1/2005 | F33: 2958465 | G33: ISO | H33: No | I33: Admitted | J33: Endorsement | K33: Static | L33: N/A | M33: No | Q33: X | CA33: Optional | CB33: Defined by Rule | CC33: Yes | CD33: SINGLE
B34: MICHIGAN CHANGES | C34: CG 01 68 | D34: 1120 | E34: 11/1/2020 | F34: 2958465 | G34: ISO | H34: No | I34: Admitted | J34: Policy Notice | K34: Static | L34: N/A | M34: No | Q34: X | T34: X | U34: X | V34: X | CA34: Mandatory | CB34: No additional conditions | CC34: Yes | CD34: SINGLE
B35: COLORADO CHANGES | C35: CG 01 72 | D35: 413 | E35: 4/1/2013 | F35: 2958465 | G35: ISO | H35: No | I35: Admitted | J35: Policy Notice | K35: Static | L35: N/A | M35: No | Q35: X | CA35: Mandatory | CB35: No additional conditions | CC35: Yes | CD35: SINGLE
B36: COLORADO CHANGES | C36: CG 01 73 | D36: 1093 | E36: 12/1/1993 | F36: 2958465 | G36: ISO | H36: No | I36: Admitted | J36: Policy Notice | K36: Static | L36: N/A | M36: No | T36: X | CA36: Mandatory | CB36: No additional conditions | CC36: Yes | CD36: SINGLE
B37: COLORADO CHANGES | C37: CG 01 74 | D37: 1093 | E37: 12/1/1993 | F37: 2958465 | G37: ISO | H37: No | I37: Admitted | J37: Policy Notice | K37: Static | L37: N/A | M37: No | W37: X | CA37: Mandatory | CB37: No additional conditions | CC37: Yes | CD37: SINGLE
B38: PENNSYLVANIA CHANGES LOSS INFORMATION | C38: CG 01 75 | D38: 1093 | E38: 9/1/1994 | F38: 2958465 | G38: ISO | H38: No | I38: Admitted | J38: Policy Notice | K38: Static | L38: N/A | M38: No | Q38: X | CA38: Mandatory | CB38: No additional conditions | CC38: Yes | CD38: SINGLE
B39: PENNSYLVANIA CHANGES LOSS INFORMATION | C39: CG 01 76 | D39: 1093 | E39: 9/1/1994 | F39: 2958465 | G39: ISO | H39: No | I39: Admitted | J39: Policy Notice | K39: Static | L39: N/A | M39: No | W39: X | CA39: Mandatory | CB39: No additional conditions | CC39: Yes | CD39: SINGLE
B40: PENNSYLVANIA CHANGES - LOSS INFORMATION | C40: CG 01 77 | D40: 1093 | E40: 9/1/1994 | F40: 2958465 | G40: ISO | H40: No | I40: Admitted | J40: Policy Notice | K40: Static | L40: N/A | M40: No | T40: X | CA40: Mandatory | CB40: No additional conditions | CC40: Yes | CD40: SINGLE
...

Sheet Dynamic Data
A1: DYNAMIC DATA FIELDS
A2: Client: | B2: <Client Name>
A3: Phase: | B3: <Placeholder>
A4: FORM DETAILS | C4: DYNAMIC FIELD DETAILS | I4: UI FIELD DETAILS (DEVELOPMENT ONLY)
A5: FORM NO. | B5: FORM NAME | C5: DYNAMIC FIELD NAME | D5: DATA TYPE | E5: CONDITION/RULE | F5: ITERATIVE | G5: EFFECTIVE DATE OF DYNAMIC FIELD | H5: EXPIRATION DATE OF DYNAMIC FIELD | I5: UI FIELD ID | J5: UI CAPTION | K5: FIELD XPATH | L5: PROPRIETARY | M5: NOTES
A6: CG 20 10 | B6: ADDITIONAL INSURED - OWNERS, LESSEES OR CONTRACTORS - SCHEDULED PERSON OR ORGANIZATION | C6: Name Of Additional Insured Person(s) Or Organization(s) | D6: Text | E6: Name of Additional Insured - Owners, Contractors and Trustees | F6: Yes | H6: 2958465 | L6: #N/A
A7: CG 20 10 | B7: ADDITIONAL INSURED - OWNERS, LESSEES OR CONTRACTORS - SCHEDULED PERSON OR ORGANIZATION | C7: Location(s) Of Covered Operations | D7: Text | E7: Additional Insured Location of covered operations | F7: Yes | H7: 2958465 | L7: #N/A
A8: CG 04 70 | B8: MISSOURI LIMITED PRODUCT WITHDRAWAL EXPENSE ENDORSEMENT | C8: Aggregate Limit | D8: Number | E8: Aggregate limit for the indicated Limited Product Withdrawal Expense | F8: No | H8: 2958465 | L8: No
A9: CG 04 70 | B9: MISSOURI LIMITED PRODUCT WITHDRAWAL EXPENSE ENDORSEMENT | C9: Deductible Amount Per Product Withdrawal | D9: Number | E9: The deductible amount per product withdrawal the insured must pay before a claim is paid | F9: No | H9: 2958465 | L9: No
A10: CG 04 70 | B10: MISSOURI LIMITED PRODUCT WITHDRAWAL EXPENSE ENDORSEMENT | C10: Participation Percentage Per Product Withdrawal | D10: Number | E10: Participation Percentage Per Product Withdrawal | F10: No | H10: 2958465 | L10: No
A11: CG 04 70 | B11: MISSOURI LIMITED PRODUCT WITHDRAWAL EXPENSE ENDORSEMENT | C11: Cut-Off Date | D11: Date | E11: The date after which the insurer is not liable for losses | F11: No | H11: 2958465 | L11: No
A12: CG 31 22 | B12: ILLINOIS CHANGES - LIQUOR LIABILITY | C12: Each Person Bodily Injury Limit | D12: Number | E12: Each Person Bodily Injury limit for the indicated Liquor Liability coverage | F12: No | H12: 2958465 | L12: No
A13: CG 31 22 | B13: ILLINOIS CHANGES - LIQUOR LIABILITY | C13: Each Person Property Damage Limit | D13: Number | E13: Each Person Property Damage limit for the indicated Liquor Liability coverage | F13: No | H13: 2958465 | L13: No
A14: CG 31 22 | B14: ILLINOIS CHANGES - LIQUOR LIABILITY | C14: Loss of Means Of Support or Loss of Society Limit | D14: Number | E14: Loss of Society Limit for the indicated liquor liability coverage | F14: No | H14: 2958465 | L14: No
A15: CG 31 22 | B15: ILLINOIS CHANGES - LIQUOR LIABILITY | C15: POLICY NUMBER: | D15: AlphaNumeric | E15: Number of the corresponding policy | F15: No | H15: 2958465 | L15: No
A16: CG 24 12 | B16: BOATS | C16: Description of Watercraft: | D16: Text | E16: Detailed description of the covered watercraft | F16: Yes | H16: 2958465 | L16: No
A17: CG 24 12 | B17: BOATS | C17: Additional Premium: | D17: Currency | E17: Additional Premium to be charged for the Boats coverage | F17: No | H17: 2958465 | L17: No
A18: CG 02 24 | B18: EARLIER NOTICE OF CANCELLATION PROVIDED BY US | C18: POLICY NUMBER: | D18: AlphaNumeric | E18: Number of the corresponding policy | F18: No | H18: 2958465 | L18: No
A19: CG 02 24 | B19: EARLIER NOTICE OF CANCELLATION PROVIDED BY US | C19: Number of Days' Notice | D19: Text | E19: Number of days notice provided by the company required for cancellation | F19: No | H19: 2958465 | L19: No
... A418: CG 99 10 | B418: PREMIUM AUDIT NONCOMPLIANCE CHARGE | C418: Reassessment Charge: | D418: Number | E418: Reassessment charge | F418: No | H418: 2958465 | L418: No
A419: CG 20 10 | B419: ADDITIONAL INSURED - OWNERS, LESSEES OR CONTRACTORS - SCHEDULED PERSON OR ORGANIZATION | C419: POLICY NUMBER: | D419: AlphaNumeric | E419: Number of the corresponding policy | F419: No | H419: 2958465 | L419: #N/A
A420: CG 20 10 | B420: ADDITIONAL INSURED - OWNERS, LESSEES OR CONTRACTORS - SCHEDULED PERSON OR ORGANIZATION | C420: Name Of Additional Insured Person(s) Or Organization(s) | D420: Text | E420: Names of additional insured persons or organizations | F420: Yes | H420: 2958465 | L420: #N/A
A421: CG 20 10 | B421: ADDITIONAL INSURED - OWNERS, LESSEES OR CONTRACTORS - SCHEDULED PERSON OR ORGANIZATION | C421: Location(s) Of Covered Operations | D421: Text | E421: Locations of covered operations | F421: Yes | H421: 2958465 | L421: #N/A
A422: CG 20 37 | B422: ADDITIONAL INSURED - OWNERS, LESSEES OR CONTRACTORS - COMPLETED OPERATIONS | C422: Name of Person or Organization : | D422: Text | E422: Detailed description of the person or organization where coverage is included | F422: No | H422: 2958465 | L422: No
A423: CG 04 32 | B423: YEAR 2000 COMPUTER-RELATED AND OTHER ELECTRONIC PROBLEMS – LIMITED COVERAGE OPTIONS | C423: POLICY NUMBER: | D423: AlphaNumeric | E423: Number of the corresponding policy | F423: No | H423: 2958465 | L423: No
A424: CG 04 32 | B424: YEAR 2000 COMPUTER-RELATED AND OTHER ELECTRONIC PROBLEMS – LIMITED COVERAGE OPTIONS | C424: Bodily Injury | D424: Text | E424: Indicate with an 'X' if the Bodily Injury Coverage is to be excluded | F424: Yes | H424: 2958465 | L424: No
A425: CG 04 32 | B425: YEAR 2000 COMPUTER-RELATED AND OTHER ELECTRONIC PROBLEMS – LIMITED COVERAGE OPTIONS | C425: Property Damage | D425: Text | E425: Indicate with an 'X' if the Property Damage Coverage is to be excluded | F425: Yes | H425: 2958465 | L425: No
A426: CG 04 32 | B426: YEAR 2000 COMPUTER-RELATED AND OTHER ELECTRONIC PROBLEMS | C426: Description of product(s) or completed operations | D426: Text | E426: Detailed description of the product(s) or completed operations | F426: Yes | H426: 2958465 | L426: No
A427: CG 04 32 | B427: YEAR 2000 COMPUTER-RELATED AND OTHER ELECTRONIC PROBLEMS – LIMITED COVERAGE OPTIONS | C427: Premium | D427: Currency | E427: Premium to be charged for the coverage | F427: No | H427: 2958465 | L427: No
A428: CG 20 10 | B428: ADDITIONAL INSURED - OWNERS, LESSEES OR CONTRACTORS - SCHEDULED PERSON OR ORGANIZATION | C428: POLICY NUMBER: | D428: AlphaNumeric | E428: Number of the corresponding policy | F428: No | H428: 2958465 | L428: No
A429: CG 20 10 | B429: ADDITIONAL INSURED - OWNERS, LESSEES OR CONTRACTORS - SCHEDULED PERSON OR ORGANIZATION | C429: Name of Additional Insured Person(s) or Organizations(s) | D429: Text | E429: Names of additional insured persons or organizations | F429: Yes | H429: 2958465 | L429: No
A430: CG 20 10 | B430: ADDITIONAL INSURED - OWNERS, LESSEES OR CONTRACTORS - SCHEDULED PERSON OR ORGANIZATION | C430: Location(s) of Covered Operations | D430: Text | E430: Description of locations of covered operations | F430: Yes | H430: 2958465 | L430: No
A431: CG 20 29 | B431: ADDITIONAL INSURED - GRANTOR OF FRANCHISE | C431: POLICY NUMBER: | D431: AlphaNumeric | E431: Number of the corresponding policy | F431: No | H431: 2958465 | L431: No
A432: CG 20 29 | B432: ADDITIONAL INSURED - GRANTOR OF FRANCHISE | C432: Name(s) Of Person(s) or Organization(s) | D432: Text | E432: Names of persons or organizations | F432: Yes | H432: 2958465 | L432: No
A433: CG 34 01 | B433: ADDITIONAL INSURED - OWNERS, MANAGERS OR LESSORS OF PREMISES - LIQUOR LIABILITY | C433: POLICY NUMBER: | D433: AlphaNumeric | E433: Number of the corresponding policy | F433: No | H433: 2958465 | L433: No
... A572: CG 28 79 | B572: ILLINOIS EXTENDED REPORTING PERIOD ENDORSEMENT | C572: Premium $ | D572: Currency | E572: Indicates the premium for the indicated Pollution Liability Coverage | F572: No | H572: 2958465 | L572: No
A573: CG 20 37 (10 01 only) | B573: ADDITIONAL INSURED-OWNERS, LESSEES OR CONTRACTORS-COMPLETED OPERATIONS | C573: Additional Premium : | D573: Currency | E573: Additional Premium for the indicated coverage, if applicable | F573: No | H573: 2958465
A574: CG 24 28 | B574: INDIANA CHANGES – AMENDMENT OF DEFINITION OF POLLUTANTS | C574: POLICY NUMBER : | D574: AlphaNumeric | E574: Number of the corresponding policy | F574: No | H574: 2958465 | L574: No
A575: CG 24 28 | B575: INDIANA CHANGES – AMENDMENT OF DEFINITION OF POLLUTANTS | C575: Specifically Identified Substances or Materials | D575: Text | E575: Description of Specifically Identified Substances or Materials | F575: No | H575: 2958465 | L575: No
A576: ILE 0255 | B576: CONSTRUCTION LIMITATION WITH LIMITED EARTH MOVEMENT EVENT COVERAGE | C576: Limits Of Insurance : Each Earth Movement Limit | D576: Currency | E576: Indicates limit per earth movement | F576: No | H576: 2958465
...

Sheet Headers & Footers
A1: HEADERS & FOOTERS - DYNAMIC DATA FIELDS
A2: Client: | B2: <Client Name> Insurance Companies
A3: Phase: | B3: Product Simplification
A4: FORM DETAILS | C4: HEADER / FOOTER DETAILS
A5: FORM NO. | B5: FORM NAME | C5: FIELD NAME | D5: HEADER / FOOTER | E5: DYNAMIC / STATIC
A6: CGD 0001 | B6: COMMERCIAL GENERAL LIABILITY COVERAGE PART DECLARATIONS | C6: LOGO | D6: Header | E6: Static
A7: CGD 0001 | B7: COMMERCIAL GENERAL LIABILITY COVERAGE PART DECLARATIONS | C7: COMPANY NAME | D7: Header | E7: Dynamic
A8: CGD 0001 | B8: COMMERCIAL GENERAL LIABILITY COVERAGE PART DECLARATIONS | C8: COVERAGE TYPE | D8: Header | E8: Dynamic
A9: CGD 0001 | B9: COMMERCIAL GENERAL LIABILITY COVERAGE PART DECLARATIONS | C9: PACKAGE COVERAGE PART | D9: Header | E9: Dynamic
A10: CGD 0001 | B10: COMMERCIAL GENERAL LIABILITY COVERAGE PART DECLARATIONS | C10: TRANSACTION NAME | D10: Header | E10: Dynamic
A11: CGD 0001 | B11: COMMERCIAL GENERAL LIABILITY COVERAGE PART DECLARATIONS | C11: FORM NUMBER | D11: Footer | E11: Dynamic
A12: CGD 0001 | B12: COMMERCIAL GENERAL LIABILITY COVERAGE PART DECLARATIONS | C12: PRINT DATE | D12: Footer | E12: Dynamic
A13: CGD 0001 | B13: COMMERCIAL GENERAL LIABILITY COVERAGE PART DECLARATIONS | C13: ENTRY PERSON ID | D13: Footer | E13: Dynamic
A14: CGD 0001 | B14: COMMERCIAL GENERAL LIABILITY COVERAGE PART DECLARATIONS | C14: COMMISSION CODE | D14: Footer | E14: Dynamic
A15: CGD 0001 | B15: COMMERCIAL GENERAL LIABILITY COVERAGE PART DECLARATIONS | C15: BILL PLAN CODE | D15: Footer | E15: Dynamic
A16: CGD 0001 | B16: COMMERCIAL GENERAL LIABILITY COVERAGE PART DECLARATIONS | C16: SUB-AGENT CODE | D16: Footer | E16: Dynamic
... A82: RRD 0006 | B82: GENERAL CHANGE ENDORSEMENT - RAILROAD PROTECTIVE LIABILITY | C82: SUB-AGENT CODE | D82: Footer | E82: Dynamic

Sheet Data Validation
A1: LIST OF FORMS DROPDOWNS (ALWAYS STAYS HIDDEN)
A2: Client: | B2: <Client Name> Insurance Companies
A3: Phase: | B3: Product Simplification
A4: ADMITTED/NON-ADMITTED | B4: MANDATORY/ OPTIONAL/CONDITIONAL | C4: FORM CATEGORY | D4: DYNAMIC / STATIC | E4: <Client Name> PREMIUM BEARING | F4: SINGLE OR MULTI -USE | G4: PROPRIETARY | H4: BUREAU | I4: DISPLAY ON FORMS SCHEDULE | J4: ITERATIVE | K4: PRODUCT SIMPLIFICATION STATUS | L4: FORM STATUS | M4: SUPPRESS | N4: DATA TYPE | O4: INDICATOR | P4: SPECIALTY IMPLEMENTATION PRIORITY | Q4: HEADER / FOOTER
A5: Admitted | B5: Mandatory | C5: Declaration/ Schedule | D5: Static | E5: Yes | F5: SINGLE | G5: Yes | H5: ISO | I5: Yes | J5: Yes | K5: Not Started | L5: In Progress | M5: Yes | N5: Text | O5: X | P5: High | Q5: Header
A6: Non-Admitted | B6: Optional | C6: Policy Notice | D6: Dynamic | E6: No | F6: MULTI | G6: No | H6: ACORD | I6: No | J6: No | K6: Ready for Review - Draft | L6: Not Started | M6: No | N6: Number | P6: Medium | Q6: Footer
B7: Conditional | C7: Base Coverage Form | H7: AAIS | K7: Business Review - In Progress | L7: Completed | N7: Date | P7: Low
C8: Endorsement | H8: NCCI | K8: Approved - Completed | N8: AlphaNumeric | P8: N/A (DC OOB)
C9: Exclusion | H9: N/A | N9: Address
C10: Other Policy Documents | N10: Currency
C11: Trailing Documents
C12: Marketing Materials
